# Goxel 0.11.0
# One line per voxel
# X Y Z RRGGBB
0 0 0 37946e
1 0 0 37946e
2 0 0 37946e
3 0 0 37946e
4 0 0 37946e
5 0 0 37946e
6 0 0 37946e
7 0 0 37946e
8 0 0 37946e
9 0 0 37946e
10 0 0 37946e
11 0 0 37946e
12 0 0 37946e
13 0 0 37946e
14 0 0 37946e
15 0 0 37946e
0 1 0 37946e
1 1 0 37946e
2 1 0 37946e
3 1 0 37946e
4 1 0 37946e
5 1 0 37946e
6 1 0 37946e
7 1 0 37946e
8 1 0 37946e
9 1 0 37946e
10 1 0 37946e
14 1 0 37946e
15 1 0 37946e
0 2 0 37946e
1 2 0 37946e
6 2 0 37946e
7 2 0 37946e
9 2 0 37946e
10 2 0 37946e
11 2 0 37946e
12 2 0 37946e
13 2 0 37946e
14 2 0 37946e
15 2 0 37946e
0 3 0 37946e
1 3 0 37946e
0 4 0 37946e
1 4 0 37946e
0 5 0 37946e
1 5 0 37946e
0 6 0 37946e
1 6 0 37946e
0 7 0 37946e
1 7 0 37946e
0 8 0 37946e
1 8 0 37946e
0 9 0 37946e
1 9 0 37946e
0 10 0 37946e
1 10 0 37946e
0 11 0 37946e
1 11 0 37946e
0 12 0 37946e
1 12 0 37946e
0 13 0 37946e
1 13 0 37946e
0 14 0 37946e
1 14 0 37946e
0 15 0 37946e
1 15 0 37946e
6 15 0 ac3232
7 15 0 ac3232
8 15 0 ac3232
9 15 0 ac3232
10 15 0 ac3232
11 15 0 ac3232
3 0 1 306082
4 0 1 306082
5 0 1 306082
6 0 1 306082
1 1 1 306082
2 1 1 306082
3 1 1 306082
4 1 1 306082
5 1 1 306082
6 1 1 306082
7 1 1 306082
8 1 1 306082
1 2 1 306082
2 2 1 306082
3 2 1 306082
4 2 1 306082
5 2 1 306082
6 2 1 306082
7 2 1 306082
8 2 1 306082
0 3 1 306082
1 3 1 306082
2 3 1 306082
3 3 1 306082
4 3 1 306082
5 3 1 306082
6 3 1 306082
7 3 1 306082
8 3 1 306082
9 3 1 306082
0 4 1 306082
1 4 1 306082
2 4 1 306082
3 4 1 306082
4 4 1 306082
5 4 1 306082
6 4 1 306082
7 4 1 306082
8 4 1 306082
9 4 1 306082
0 5 1 306082
1 5 1 306082
2 5 1 306082
3 5 1 306082
4 5 1 306082
5 5 1 306082
6 5 1 306082
7 5 1 306082
8 5 1 306082
9 5 1 306082
0 6 1 306082
1 6 1 306082
2 6 1 306082
3 6 1 306082
4 6 1 306082
5 6 1 306082
6 6 1 306082
7 6 1 306082
8 6 1 306082
9 6 1 306082
1 7 1 306082
2 7 1 306082
3 7 1 306082
4 7 1 306082
5 7 1 306082
6 7 1 306082
7 7 1 306082
8 7 1 306082
1 8 1 306082
2 8 1 306082
3 8 1 306082
4 8 1 306082
5 8 1 306082
6 8 1 306082
7 8 1 306082
8 8 1 306082
3 9 1 306082
4 9 1 306082
5 9 1 306082
6 9 1 306082
6 15 1 ac3232
7 15 1 ac3232
8 15 1 ac3232
9 15 1 ac3232
10 15 1 ac3232
11 15 1 ac3232
3 0 2 306082
4 0 2 306082
5 0 2 306082
6 0 2 306082
1 1 2 306082
2 1 2 306082
3 1 2 306082
4 1 2 306082
5 1 2 306082
6 1 2 306082
7 1 2 306082
8 1 2 306082
1 2 2 306082
2 2 2 306082
3 2 2 306082
4 2 2 306082
5 2 2 306082
6 2 2 306082
7 2 2 306082
8 2 2 306082
0 3 2 306082
1 3 2 306082
2 3 2 306082
3 3 2 306082
4 3 2 306082
5 3 2 306082
6 3 2 306082
7 3 2 306082
8 3 2 306082
9 3 2 306082
0 4 2 306082
1 4 2 306082
2 4 2 306082
3 4 2 306082
4 4 2 306082
5 4 2 306082
6 4 2 306082
7 4 2 306082
8 4 2 306082
9 4 2 306082
0 5 2 306082
1 5 2 306082
2 5 2 306082
3 5 2 306082
4 5 2 306082
5 5 2 306082
6 5 2 306082
7 5 2 306082
8 5 2 306082
9 5 2 306082
0 6 2 306082
1 6 2 306082
2 6 2 306082
3 6 2 306082
4 6 2 306082
5 6 2 306082
6 6 2 306082
7 6 2 306082
8 6 2 306082
9 6 2 306082
1 7 2 306082
2 7 2 306082
3 7 2 306082
4 7 2 306082
5 7 2 306082
6 7 2 306082
7 7 2 306082
8 7 2 306082
1 8 2 306082
2 8 2 306082
3 8 2 306082
4 8 2 306082
5 8 2 306082
6 8 2 306082
7 8 2 306082
8 8 2 306082
3 9 2 306082
4 9 2 306082
5 9 2 306082
6 9 2 306082
6 15 2 ac3232
7 15 2 ac3232
8 15 2 ac3232
9 15 2 ac3232
10 15 2 ac3232
11 15 2 ac3232
3 0 3 306082
4 0 3 306082
5 0 3 306082
6 0 3 306082
1 1 3 306082
2 1 3 306082
3 1 3 306082
4 1 3 306082
5 1 3 306082
6 1 3 306082
7 1 3 306082
8 1 3 306082
1 2 3 306082
2 2 3 306082
3 2 3 306082
4 2 3 306082
5 2 3 306082
6 2 3 306082
7 2 3 306082
8 2 3 306082
0 3 3 306082
1 3 3 306082
2 3 3 306082
3 3 3 306082
4 3 3 306082
5 3 3 306082
6 3 3 306082
7 3 3 306082
8 3 3 306082
9 3 3 306082
0 4 3 306082
1 4 3 306082
2 4 3 306082
3 4 3 306082
4 4 3 306082
5 4 3 306082
6 4 3 306082
7 4 3 306082
8 4 3 306082
9 4 3 306082
0 5 3 306082
1 5 3 306082
2 5 3 306082
3 5 3 306082
4 5 3 306082
5 5 3 306082
6 5 3 306082
7 5 3 306082
8 5 3 306082
9 5 3 306082
0 6 3 306082
1 6 3 306082
2 6 3 306082
3 6 3 306082
4 6 3 306082
5 6 3 306082
6 6 3 306082
7 6 3 306082
8 6 3 306082
9 6 3 306082
1 7 3 306082
2 7 3 306082
3 7 3 306082
4 7 3 306082
5 7 3 306082
6 7 3 306082
7 7 3 306082
8 7 3 306082
1 8 3 306082
2 8 3 306082
3 8 3 306082
4 8 3 306082
5 8 3 306082
6 8 3 306082
7 8 3 306082
8 8 3 306082
3 9 3 306082
4 9 3 306082
5 9 3 306082
6 9 3 306082
6 15 3 ac3232
7 15 3 ac3232
8 15 3 ac3232
9 15 3 ac3232
10 15 3 ac3232
11 15 3 ac3232
3 0 4 306082
4 0 4 306082
5 0 4 306082
6 0 4 306082
1 1 4 306082
2 1 4 306082
3 1 4 306082
4 1 4 306082
5 1 4 306082
6 1 4 306082
7 1 4 306082
8 1 4 306082
1 2 4 306082
2 2 4 306082
3 2 4 306082
4 2 4 306082
5 2 4 306082
6 2 4 306082
7 2 4 306082
8 2 4 306082
0 3 4 306082
1 3 4 306082
2 3 4 306082
3 3 4 306082
4 3 4 306082
5 3 4 306082
6 3 4 306082
7 3 4 306082
8 3 4 306082
9 3 4 306082
0 4 4 306082
1 4 4 306082
2 4 4 306082
3 4 4 306082
4 4 4 306082
5 4 4 306082
6 4 4 306082
7 4 4 306082
8 4 4 306082
9 4 4 306082
0 5 4 306082
1 5 4 306082
2 5 4 306082
3 5 4 306082
4 5 4 306082
5 5 4 306082
6 5 4 306082
7 5 4 306082
8 5 4 306082
9 5 4 306082
0 6 4 306082
1 6 4 306082
2 6 4 306082
3 6 4 306082
4 6 4 306082
5 6 4 306082
6 6 4 306082
7 6 4 306082
8 6 4 306082
9 6 4 306082
1 7 4 306082
2 7 4 306082
3 7 4 306082
4 7 4 306082
5 7 4 306082
6 7 4 306082
7 7 4 306082
8 7 4 306082
1 8 4 306082
2 8 4 306082
3 8 4 306082
4 8 4 306082
5 8 4 306082
6 8 4 306082
7 8 4 306082
8 8 4 306082
3 9 4 306082
4 9 4 306082
5 9 4 306082
6 9 4 306082
6 15 4 ac3232
7 15 4 ac3232
8 15 4 ac3232
9 15 4 ac3232
10 15 4 ac3232
11 15 4 ac3232
3 0 5 306082
4 0 5 306082
5 0 5 306082
6 0 5 306082
1 1 5 306082
2 1 5 306082
3 1 5 306082
4 1 5 306082
5 1 5 306082
6 1 5 306082
7 1 5 306082
8 1 5 306082
1 2 5 306082
2 2 5 306082
3 2 5 306082
4 2 5 306082
5 2 5 306082
6 2 5 306082
7 2 5 306082
8 2 5 306082
0 3 5 306082
1 3 5 306082
2 3 5 306082
3 3 5 306082
4 3 5 306082
5 3 5 306082
6 3 5 306082
7 3 5 306082
8 3 5 306082
9 3 5 306082
0 4 5 306082
1 4 5 306082
2 4 5 306082
3 4 5 306082
4 4 5 306082
5 4 5 306082
6 4 5 306082
7 4 5 306082
8 4 5 306082
9 4 5 306082
0 5 5 306082
1 5 5 306082
2 5 5 306082
3 5 5 306082
4 5 5 306082
5 5 5 306082
6 5 5 306082
7 5 5 306082
8 5 5 306082
9 5 5 306082
0 6 5 306082
1 6 5 306082
2 6 5 306082
3 6 5 306082
4 6 5 306082
5 6 5 306082
6 6 5 306082
7 6 5 306082
8 6 5 306082
9 6 5 306082
1 7 5 306082
2 7 5 306082
3 7 5 306082
4 7 5 306082
5 7 5 306082
6 7 5 306082
7 7 5 306082
8 7 5 306082
1 8 5 306082
2 8 5 306082
3 8 5 306082
4 8 5 306082
5 8 5 306082
6 8 5 306082
7 8 5 306082
8 8 5 306082
3 9 5 306082
4 9 5 306082
5 9 5 306082
6 9 5 306082
6 15 5 ac3232
7 15 5 ac3232
8 15 5 ac3232
9 15 5 ac3232
10 15 5 ac3232
11 15 5 ac3232
3 0 6 306082
4 0 6 306082
5 0 6 306082
6 0 6 306082
1 1 6 306082
2 1 6 306082
3 1 6 306082
4 1 6 306082
5 1 6 306082
6 1 6 306082
7 1 6 306082
8 1 6 306082
1 2 6 306082
2 2 6 306082
3 2 6 306082
4 2 6 306082
5 2 6 306082
6 2 6 306082
7 2 6 306082
8 2 6 306082
0 3 6 306082
1 3 6 306082
2 3 6 306082
3 3 6 306082
4 3 6 306082
5 3 6 306082
6 3 6 306082
7 3 6 306082
8 3 6 306082
9 3 6 306082
0 4 6 306082
1 4 6 306082
2 4 6 306082
3 4 6 306082
4 4 6 306082
5 4 6 306082
6 4 6 306082
7 4 6 306082
8 4 6 306082
9 4 6 306082
0 5 6 306082
1 5 6 306082
2 5 6 306082
3 5 6 306082
4 5 6 306082
5 5 6 306082
6 5 6 306082
7 5 6 306082
8 5 6 306082
9 5 6 306082
0 6 6 306082
1 6 6 306082
2 6 6 306082
3 6 6 306082
4 6 6 306082
5 6 6 306082
6 6 6 306082
7 6 6 306082
8 6 6 306082
9 6 6 306082
1 7 6 306082
2 7 6 306082
3 7 6 306082
4 7 6 306082
5 7 6 306082
6 7 6 306082
7 7 6 306082
8 7 6 306082
1 8 6 306082
2 8 6 306082
3 8 6 306082
4 8 6 306082
5 8 6 306082
6 8 6 306082
7 8 6 306082
8 8 6 306082
3 9 6 306082
4 9 6 306082
5 9 6 306082
6 9 6 306082
6 15 6 ac3232
7 15 6 ac3232
8 15 6 ac3232
9 15 6 ac3232
10 15 6 ac3232
11 15 6 ac3232
3 0 7 306082
4 0 7 306082
5 0 7 306082
6 0 7 306082
1 1 7 306082
2 1 7 306082
3 1 7 306082
4 1 7 306082
5 1 7 306082
6 1 7 306082
7 1 7 306082
8 1 7 306082
1 2 7 306082
2 2 7 306082
3 2 7 306082
4 2 7 306082
5 2 7 306082
6 2 7 306082
7 2 7 306082
8 2 7 306082
0 3 7 306082
1 3 7 306082
2 3 7 306082
3 3 7 306082
4 3 7 306082
5 3 7 306082
6 3 7 306082
7 3 7 306082
8 3 7 306082
9 3 7 306082
0 4 7 306082
1 4 7 306082
2 4 7 306082
3 4 7 306082
4 4 7 306082
5 4 7 306082
6 4 7 306082
7 4 7 306082
8 4 7 306082
9 4 7 306082
0 5 7 306082
1 5 7 306082
2 5 7 306082
3 5 7 306082
4 5 7 306082
5 5 7 306082
6 5 7 306082
7 5 7 306082
8 5 7 306082
9 5 7 306082
0 6 7 306082
1 6 7 306082
2 6 7 306082
3 6 7 306082
4 6 7 306082
5 6 7 306082
6 6 7 306082
7 6 7 306082
8 6 7 306082
9 6 7 306082
1 7 7 306082
2 7 7 306082
3 7 7 306082
4 7 7 306082
5 7 7 306082
6 7 7 306082
7 7 7 306082
8 7 7 306082
1 8 7 306082
2 8 7 306082
3 8 7 306082
4 8 7 306082
5 8 7 306082
6 8 7 306082
7 8 7 306082
8 8 7 306082
3 9 7 306082
4 9 7 306082
5 9 7 306082
6 9 7 306082
6 15 7 ac3232
7 15 7 ac3232
8 15 7 ac3232
9 15 7 ac3232
10 15 7 ac3232
11 15 7 ac3232
3 0 8 306082
4 0 8 306082
5 0 8 306082
6 0 8 306082
1 1 8 306082
2 1 8 306082
3 1 8 306082
4 1 8 306082
5 1 8 306082
6 1 8 306082
7 1 8 306082
8 1 8 306082
1 2 8 306082
2 2 8 306082
3 2 8 306082
4 2 8 306082
5 2 8 306082
6 2 8 306082
7 2 8 306082
8 2 8 306082
0 3 8 306082
1 3 8 306082
2 3 8 306082
3 3 8 306082
4 3 8 306082
5 3 8 306082
6 3 8 306082
7 3 8 306082
8 3 8 306082
9 3 8 306082
0 4 8 306082
1 4 8 306082
2 4 8 306082
3 4 8 306082
4 4 8 306082
5 4 8 306082
6 4 8 306082
7 4 8 306082
8 4 8 306082
9 4 8 306082
0 5 8 306082
1 5 8 306082
2 5 8 306082
3 5 8 306082
4 5 8 306082
5 5 8 306082
6 5 8 306082
7 5 8 306082
8 5 8 306082
9 5 8 306082
0 6 8 306082
1 6 8 306082
2 6 8 306082
3 6 8 306082
4 6 8 306082
5 6 8 306082
6 6 8 306082
7 6 8 306082
8 6 8 306082
9 6 8 306082
1 7 8 306082
2 7 8 306082
3 7 8 306082
4 7 8 306082
5 7 8 306082
6 7 8 306082
7 7 8 306082
8 7 8 306082
1 8 8 306082
2 8 8 306082
3 8 8 306082
4 8 8 306082
5 8 8 306082
6 8 8 306082
7 8 8 306082
8 8 8 306082
3 9 8 306082
4 9 8 306082
5 9 8 306082
6 9 8 306082
6 15 8 ac3232
7 15 8 ac3232
8 15 8 ac3232
9 15 8 ac3232
10 15 8 ac3232
11 15 8 ac3232
3 0 9 306082
4 0 9 306082
5 0 9 306082
6 0 9 306082
1 1 9 306082
2 1 9 306082
3 1 9 306082
4 1 9 306082
5 1 9 306082
6 1 9 306082
7 1 9 306082
8 1 9 306082
1 2 9 306082
2 2 9 306082
3 2 9 306082
4 2 9 306082
5 2 9 306082
6 2 9 306082
7 2 9 306082
8 2 9 306082
0 3 9 306082
1 3 9 306082
2 3 9 306082
3 3 9 306082
4 3 9 306082
5 3 9 306082
6 3 9 306082
7 3 9 306082
8 3 9 306082
9 3 9 306082
0 4 9 306082
1 4 9 306082
2 4 9 306082
3 4 9 306082
4 4 9 306082
5 4 9 306082
6 4 9 306082
7 4 9 306082
8 4 9 306082
9 4 9 306082
0 5 9 306082
1 5 9 306082
2 5 9 306082
3 5 9 306082
4 5 9 306082
5 5 9 306082
6 5 9 306082
7 5 9 306082
8 5 9 306082
9 5 9 306082
0 6 9 306082
1 6 9 306082
2 6 9 306082
3 6 9 306082
4 6 9 306082
5 6 9 306082
6 6 9 306082
7 6 9 306082
8 6 9 306082
9 6 9 306082
1 7 9 306082
2 7 9 306082
3 7 9 306082
4 7 9 306082
5 7 9 306082
6 7 9 306082
7 7 9 306082
8 7 9 306082
1 8 9 306082
2 8 9 306082
3 8 9 306082
4 8 9 306082
5 8 9 306082
6 8 9 306082
7 8 9 306082
8 8 9 306082
3 9 9 306082
4 9 9 306082
5 9 9 306082
6 9 9 306082
6 15 9 ac3232
7 15 9 ac3232
8 15 9 ac3232
9 15 9 ac3232
10 15 9 ac3232
11 15 9 ac3232
3 0 10 306082
4 0 10 306082
5 0 10 306082
6 0 10 306082
1 1 10 306082
2 1 10 306082
3 1 10 306082
4 1 10 306082
5 1 10 306082
6 1 10 306082
7 1 10 306082
8 1 10 306082
1 2 10 306082
2 2 10 306082
3 2 10 306082
4 2 10 306082
5 2 10 306082
6 2 10 306082
7 2 10 306082
8 2 10 306082
0 3 10 306082
1 3 10 306082
2 3 10 306082
3 3 10 306082
4 3 10 306082
5 3 10 306082
6 3 10 306082
7 3 10 306082
8 3 10 306082
9 3 10 306082
0 4 10 306082
1 4 10 306082
2 4 10 306082
3 4 10 306082
4 4 10 306082
5 4 10 306082
6 4 10 306082
7 4 10 306082
8 4 10 306082
9 4 10 306082
0 5 10 306082
1 5 10 306082
2 5 10 306082
3 5 10 306082
4 5 10 306082
5 5 10 306082
6 5 10 306082
7 5 10 306082
8 5 10 306082
9 5 10 306082
0 6 10 306082
1 6 10 306082
2 6 10 306082
3 6 10 306082
4 6 10 306082
5 6 10 306082
6 6 10 306082
7 6 10 306082
8 6 10 306082
9 6 10 306082
1 7 10 306082
2 7 10 306082
3 7 10 306082
4 7 10 306082
5 7 10 306082
6 7 10 306082
7 7 10 306082
8 7 10 306082
1 8 10 306082
2 8 10 306082
3 8 10 306082
4 8 10 306082
5 8 10 306082
6 8 10 306082
7 8 10 306082
8 8 10 306082
3 9 10 306082
4 9 10 306082
5 9 10 306082
6 9 10 306082
6 15 10 ac3232
7 15 10 ac3232
8 15 10 ac3232
9 15 10 ac3232
10 15 10 ac3232
11 15 10 ac3232
6 15 11 ac3232
7 15 11 ac3232
8 15 11 ac3232
9 15 11 ac3232
10 15 11 ac3232
11 15 11 ac3232
6 15 12 ac3232
7 15 12 ac3232
8 15 12 ac3232
9 15 12 ac3232
10 15 12 ac3232
11 15 12 ac3232
4 13 13 ac3232
5 13 13 ac3232
3 14 13 ac3232
4 14 13 ac3232
5 14 13 ac3232
6 14 13 ac3232
2 15 13 ac3232
3 15 13 ac3232
4 15 13 ac3232
5 15 13 ac3232
6 15 13 ac3232
7 15 13 ac3232
3 12 14 ac3232
4 12 14 ac3232
5 12 14 ac3232
6 12 14 ac3232
2 13 14 ac3232
3 13 14 ac3232
4 13 14 ac3232
5 13 14 ac3232
6 13 14 ac3232
7 13 14 ac3232
1 14 14 ac3232
2 14 14 ac3232
3 14 14 ac3232
4 14 14 ac3232
5 14 14 ac3232
6 14 14 ac3232
7 14 14 ac3232
8 14 14 ac3232
1 15 14 ac3232
2 15 14 ac3232
3 15 14 ac3232
4 15 14 ac3232
5 15 14 ac3232
6 15 14 ac3232
7 15 14 ac3232
8 15 14 ac3232
3 11 15 ac3232
4 11 15 ac3232
5 11 15 ac3232
6 11 15 ac3232
2 12 15 ac3232
3 12 15 ac3232
4 12 15 ac3232
5 12 15 ac3232
6 12 15 ac3232
7 12 15 ac3232
1 13 15 ac3232
2 13 15 ac3232
3 13 15 ac3232
4 13 15 ac3232
5 13 15 ac3232
6 13 15 ac3232
7 13 15 ac3232
8 13 15 ac3232
0 14 15 ac3232
1 14 15 ac3232
2 14 15 ac3232
3 14 15 ac3232
4 14 15 ac3232
5 14 15 ac3232
6 14 15 ac3232
7 14 15 ac3232
8 14 15 ac3232
9 14 15 ac3232
0 15 15 ac3232
1 15 15 ac3232
2 15 15 ac3232
3 15 15 ac3232
4 15 15 ac3232
5 15 15 ac3232
6 15 15 ac3232
7 15 15 ac3232
8 15 15 ac3232
9 15 15 ac3232
16 0 0 37946e
17 0 0 37946e
18 0 0 37946e
19 0 0 37946e
20 0 0 37946e
21 0 0 37946e
22 0 0 37946e
23 0 0 37946e
24 0 0 37946e
25 0 0 37946e
26 0 0 37946e
27 0 0 37946e
28 0 0 37946e
29 0 0 37946e
30 0 0 37946e
31 0 0 37946e
16 1 0 37946e
17 1 0 37946e
18 1 0 37946e
19 1 0 37946e
20 1 0 37946e
21 1 0 37946e
22 1 0 37946e
23 1 0 37946e
24 1 0 37946e
25 1 0 37946e
26 1 0 37946e
27 1 0 37946e
28 1 0 37946e
29 1 0 37946e
30 1 0 37946e
31 1 0 37946e
16 2 0 37946e
17 2 0 37946e
18 2 0 37946e
19 2 0 37946e
20 2 0 37946e
21 2 0 37946e
22 2 0 37946e
23 2 0 37946e
24 2 0 37946e
25 2 0 37946e
26 2 0 37946e
27 2 0 37946e
28 2 0 37946e
29 2 0 37946e
30 2 0 37946e
31 2 0 37946e
17 3 0 37946e
18 3 0 37946e
19 3 0 37946e
20 3 0 37946e
29 3 0 37946e
30 3 0 37946e
31 3 0 37946e
29 4 0 37946e
30 4 0 37946e
31 4 0 37946e
28 5 0 37946e
29 5 0 37946e
30 5 0 37946e
31 5 0 37946e
28 6 0 37946e
29 6 0 37946e
30 6 0 37946e
31 6 0 37946e
28 7 0 37946e
29 7 0 37946e
30 7 0 37946e
31 7 0 37946e
29 8 0 37946e
30 8 0 37946e
31 8 0 37946e
29 9 0 37946e
30 9 0 37946e
31 9 0 37946e
30 10 0 37946e
31 10 0 37946e
30 11 0 37946e
30 12 0 37946e
30 13 0 37946e
29 14 0 37946e
30 14 0 37946e
29 15 0 37946e
30 15 0 37946e
0 16 0 37946e
1 16 0 37946e
3 16 0 ac3232
4 16 0 ac3232
5 16 0 ac3232
6 16 0 ac3232
7 16 0 ac3232
8 16 0 ac3232
9 16 0 ac3232
10 16 0 ac3232
11 16 0 ac3232
12 16 0 ac3232
13 16 0 ac3232
14 16 0 ac3232
0 17 0 37946e
1 17 0 37946e
2 17 0 ac3232
3 17 0 ac3232
4 17 0 ac3232
5 17 0 ac3232
6 17 0 ac3232
7 17 0 ac3232
8 17 0 ac3232
9 17 0 ac3232
10 17 0 ac3232
11 17 0 ac3232
12 17 0 ac3232
13 17 0 ac3232
14 17 0 ac3232
15 17 0 ac3232
0 18 0 37946e
1 18 0 ac3232
2 18 0 ac3232
3 18 0 ac3232
4 18 0 ac3232
5 18 0 ac3232
6 18 0 ac3232
7 18 0 ac3232
8 18 0 ac3232
9 18 0 ac3232
10 18 0 ac3232
11 18 0 ac3232
12 18 0 ac3232
13 18 0 ac3232
14 18 0 ac3232
15 18 0 ac3232
0 19 0 37946e
1 19 0 ac3232
2 19 0 ac3232
3 19 0 ac3232
4 19 0 ac3232
5 19 0 ac3232
6 19 0 ac3232
7 19 0 ac3232
8 19 0 ac3232
9 19 0 ac3232
10 19 0 ac3232
11 19 0 ac3232
12 19 0 ac3232
13 19 0 ac3232
14 19 0 ac3232
15 19 0 ac3232
0 20 0 ac3232
1 20 0 ac3232
2 20 0 ac3232
3 20 0 ac3232
4 20 0 ac3232
5 20 0 ac3232
6 20 0 ac3232
7 20 0 ac3232
8 20 0 ac3232
9 20 0 ac3232
10 20 0 ac3232
11 20 0 ac3232
12 20 0 ac3232
13 20 0 ac3232
14 20 0 ac3232
15 20 0 ac3232
0 21 0 ac3232
1 21 0 ac3232
2 21 0 ac3232
3 21 0 ac3232
4 21 0 ac3232
5 21 0 ac3232
6 21 0 ac3232
7 21 0 ac3232
8 21 0 ac3232
9 21 0 ac3232
10 21 0 ac3232
11 21 0 ac3232
12 21 0 ac3232
13 21 0 ac3232
14 21 0 ac3232
15 21 0 ac3232
0 22 0 ac3232
1 22 0 ac3232
2 22 0 ac3232
3 22 0 ac3232
4 22 0 ac3232
5 22 0 ac3232
6 22 0 ac3232
7 22 0 ac3232
8 22 0 ac3232
9 22 0 ac3232
10 22 0 ac3232
11 22 0 ac3232
12 22 0 ac3232
13 22 0 ac3232
14 22 0 ac3232
15 22 0 ac3232
0 23 0 ac3232
1 23 0 ac3232
2 23 0 ac3232
3 23 0 ac3232
4 23 0 ac3232
5 23 0 ac3232
6 23 0 ac3232
7 23 0 ac3232
8 23 0 ac3232
9 23 0 ac3232
10 23 0 ac3232
11 23 0 ac3232
12 23 0 ac3232
13 23 0 ac3232
14 23 0 ac3232
15 23 0 ac3232
0 24 0 37946e
1 24 0 ac3232
2 24 0 ac3232
3 24 0 ac3232
4 24 0 ac3232
5 24 0 ac3232
6 24 0 ac3232
7 24 0 ac3232
8 24 0 ac3232
9 24 0 ac3232
10 24 0 ac3232
11 24 0 ac3232
12 24 0 ac3232
13 24 0 ac3232
14 24 0 ac3232
15 24 0 ac3232
0 25 0 37946e
1 25 0 ac3232
2 25 0 ac3232
3 25 0 ac3232
4 25 0 ac3232
5 25 0 ac3232
6 25 0 ac3232
7 25 0 ac3232
8 25 0 ac3232
9 25 0 ac3232
10 25 0 ac3232
11 25 0 ac3232
12 25 0 ac3232
13 25 0 ac3232
14 25 0 ac3232
15 25 0 ac3232
0 26 0 37946e
1 26 0 37946e
2 26 0 ac3232
3 26 0 ac3232
4 26 0 ac3232
5 26 0 ac3232
6 26 0 ac3232
7 26 0 ac3232
8 26 0 ac3232
9 26 0 ac3232
10 26 0 ac3232
11 26 0 ac3232
12 26 0 ac3232
13 26 0 ac3232
14 26 0 ac3232
15 26 0 ac3232
0 27 0 37946e
1 27 0 37946e
3 27 0 ac3232
4 27 0 ac3232
5 27 0 ac3232
6 27 0 ac3232
7 27 0 ac3232
8 27 0 ac3232
9 27 0 ac3232
10 27 0 ac3232
11 27 0 ac3232
12 27 0 ac3232
13 27 0 ac3232
14 27 0 ac3232
0 28 0 37946e
1 28 0 37946e
6 28 0 ac3232
7 28 0 ac3232
8 28 0 ac3232
9 28 0 ac3232
10 28 0 ac3232
11 28 0 ac3232
1 29 0 37946e
10 29 0 37946e
11 29 0 37946e
12 29 0 37946e
13 29 0 37946e
14 29 0 37946e
15 29 0 37946e
1 30 0 37946e
2 30 0 37946e
3 30 0 37946e
4 30 0 37946e
5 30 0 37946e
6 30 0 37946e
7 30 0 37946e
8 30 0 37946e
9 30 0 37946e
10 30 0 37946e
11 30 0 37946e
12 30 0 37946e
13 30 0 37946e
14 30 0 37946e
15 30 0 37946e
1 31 0 37946e
2 31 0 37946e
3 31 0 37946e
4 31 0 37946e
5 31 0 37946e
6 31 0 37946e
7 31 0 37946e
10 31 0 37946e
11 31 0 37946e
12 31 0 37946e
13 31 0 37946e
14 31 0 37946e
15 31 0 37946e
3 16 1 ac3232
4 16 1 ac3232
5 16 1 ac3232
6 16 1 ac3232
7 16 1 ac3232
8 16 1 ac3232
9 16 1 ac3232
10 16 1 ac3232
11 16 1 ac3232
12 16 1 ac3232
13 16 1 ac3232
14 16 1 ac3232
0 17 1 37946e
1 17 1 37946e
2 17 1 ac3232
3 17 1 ac3232
4 17 1 ac3232
5 17 1 ac3232
6 17 1 ac3232
7 17 1 ac3232
8 17 1 ac3232
9 17 1 ac3232
10 17 1 ac3232
11 17 1 ac3232
12 17 1 ac3232
13 17 1 ac3232
14 17 1 ac3232
15 17 1 ac3232
0 18 1 37946e
1 18 1 ac3232
2 18 1 ac3232
3 18 1 ac3232
4 18 1 ac3232
5 18 1 ac3232
6 18 1 ac3232
7 18 1 ac3232
8 18 1 ac3232
9 18 1 ac3232
10 18 1 ac3232
11 18 1 ac3232
12 18 1 ac3232
13 18 1 ac3232
14 18 1 ac3232
15 18 1 ac3232
1 19 1 ac3232
2 19 1 ac3232
3 19 1 ac3232
4 19 1 ac3232
5 19 1 ac3232
6 19 1 ac3232
7 19 1 ac3232
8 19 1 ac3232
9 19 1 ac3232
10 19 1 ac3232
11 19 1 ac3232
12 19 1 ac3232
13 19 1 ac3232
14 19 1 ac3232
15 19 1 ac3232
0 20 1 ac3232
1 20 1 ac3232
2 20 1 ac3232
3 20 1 ac3232
4 20 1 ac3232
5 20 1 ac3232
6 20 1 ac3232
7 20 1 ac3232
8 20 1 ac3232
9 20 1 ac3232
10 20 1 ac3232
11 20 1 ac3232
12 20 1 ac3232
13 20 1 ac3232
14 20 1 ac3232
15 20 1 ac3232
0 21 1 ac3232
1 21 1 ac3232
2 21 1 ac3232
3 21 1 ac3232
4 21 1 ac3232
5 21 1 ac3232
6 21 1 ac3232
7 21 1 ac3232
8 21 1 ac3232
9 21 1 ac3232
10 21 1 ac3232
11 21 1 ac3232
12 21 1 ac3232
13 21 1 ac3232
14 21 1 ac3232
15 21 1 ac3232
0 22 1 ac3232
1 22 1 ac3232
2 22 1 ac3232
3 22 1 ac3232
4 22 1 ac3232
5 22 1 ac3232
6 22 1 ac3232
7 22 1 ac3232
8 22 1 ac3232
9 22 1 ac3232
10 22 1 ac3232
11 22 1 ac3232
12 22 1 ac3232
13 22 1 ac3232
14 22 1 ac3232
15 22 1 ac3232
0 23 1 ac3232
1 23 1 ac3232
2 23 1 ac3232
3 23 1 ac3232
4 23 1 ac3232
5 23 1 ac3232
6 23 1 ac3232
7 23 1 ac3232
8 23 1 ac3232
9 23 1 ac3232
10 23 1 ac3232
11 23 1 ac3232
12 23 1 ac3232
13 23 1 ac3232
14 23 1 ac3232
15 23 1 ac3232
1 24 1 ac3232
2 24 1 ac3232
3 24 1 ac3232
4 24 1 ac3232
5 24 1 ac3232
6 24 1 ac3232
7 24 1 ac3232
8 24 1 ac3232
9 24 1 ac3232
10 24 1 ac3232
11 24 1 ac3232
12 24 1 ac3232
13 24 1 ac3232
14 24 1 ac3232
15 24 1 ac3232
1 25 1 ac3232
2 25 1 ac3232
3 25 1 ac3232
4 25 1 ac3232
5 25 1 ac3232
6 25 1 ac3232
7 25 1 ac3232
8 25 1 ac3232
9 25 1 ac3232
10 25 1 ac3232
11 25 1 ac3232
12 25 1 ac3232
13 25 1 ac3232
14 25 1 ac3232
15 25 1 ac3232
2 26 1 ac3232
3 26 1 ac3232
4 26 1 ac3232
5 26 1 ac3232
6 26 1 ac3232
7 26 1 ac3232
8 26 1 ac3232
9 26 1 ac3232
10 26 1 ac3232
11 26 1 ac3232
12 26 1 ac3232
13 26 1 ac3232
14 26 1 ac3232
15 26 1 ac3232
3 27 1 ac3232
4 27 1 ac3232
5 27 1 ac3232
6 27 1 ac3232
7 27 1 ac3232
8 27 1 ac3232
9 27 1 ac3232
10 27 1 ac3232
11 27 1 ac3232
12 27 1 ac3232
13 27 1 ac3232
14 27 1 ac3232
6 28 1 ac3232
7 28 1 ac3232
8 28 1 ac3232
9 28 1 ac3232
10 28 1 ac3232
11 28 1 ac3232
3 16 2 ac3232
4 16 2 ac3232
5 16 2 ac3232
6 16 2 ac3232
7 16 2 ac3232
8 16 2 ac3232
9 16 2 ac3232
10 16 2 ac3232
11 16 2 ac3232
12 16 2 ac3232
13 16 2 ac3232
14 16 2 ac3232
0 17 2 37946e
1 17 2 37946e
2 17 2 ac3232
3 17 2 ac3232
4 17 2 ac3232
5 17 2 ac3232
6 17 2 ac3232
7 17 2 ac3232
8 17 2 ac3232
9 17 2 ac3232
10 17 2 ac3232
11 17 2 ac3232
12 17 2 ac3232
13 17 2 ac3232
14 17 2 ac3232
15 17 2 ac3232
0 18 2 37946e
1 18 2 ac3232
2 18 2 ac3232
3 18 2 ac3232
4 18 2 ac3232
5 18 2 ac3232
6 18 2 ac3232
7 18 2 ac3232
8 18 2 ac3232
9 18 2 ac3232
10 18 2 ac3232
11 18 2 ac3232
12 18 2 ac3232
13 18 2 ac3232
14 18 2 ac3232
15 18 2 ac3232
1 19 2 ac3232
2 19 2 ac3232
3 19 2 ac3232
4 19 2 ac3232
5 19 2 ac3232
6 19 2 ac3232
7 19 2 ac3232
8 19 2 ac3232
9 19 2 ac3232
10 19 2 ac3232
11 19 2 ac3232
12 19 2 ac3232
13 19 2 ac3232
14 19 2 ac3232
15 19 2 ac3232
0 20 2 ac3232
1 20 2 ac3232
2 20 2 ac3232
3 20 2 ac3232
4 20 2 ac3232
5 20 2 ac3232
6 20 2 ac3232
7 20 2 ac3232
8 20 2 ac3232
9 20 2 ac3232
10 20 2 ac3232
11 20 2 ac3232
12 20 2 ac3232
13 20 2 ac3232
14 20 2 ac3232
15 20 2 ac3232
0 21 2 ac3232
1 21 2 ac3232
2 21 2 ac3232
3 21 2 ac3232
4 21 2 ac3232
5 21 2 ac3232
6 21 2 ac3232
7 21 2 ac3232
8 21 2 ac3232
9 21 2 ac3232
10 21 2 ac3232
11 21 2 ac3232
12 21 2 ac3232
13 21 2 ac3232
14 21 2 ac3232
15 21 2 ac3232
0 22 2 ac3232
1 22 2 ac3232
2 22 2 ac3232
3 22 2 ac3232
4 22 2 ac3232
5 22 2 ac3232
6 22 2 ac3232
7 22 2 ac3232
8 22 2 ac3232
9 22 2 ac3232
10 22 2 ac3232
11 22 2 ac3232
12 22 2 ac3232
13 22 2 ac3232
14 22 2 ac3232
15 22 2 ac3232
0 23 2 ac3232
1 23 2 ac3232
2 23 2 ac3232
3 23 2 ac3232
4 23 2 ac3232
5 23 2 ac3232
6 23 2 ac3232
7 23 2 ac3232
8 23 2 ac3232
9 23 2 ac3232
10 23 2 ac3232
11 23 2 ac3232
12 23 2 ac3232
13 23 2 ac3232
14 23 2 ac3232
15 23 2 ac3232
1 24 2 ac3232
2 24 2 ac3232
3 24 2 ac3232
4 24 2 ac3232
5 24 2 ac3232
6 24 2 ac3232
7 24 2 ac3232
8 24 2 ac3232
9 24 2 ac3232
10 24 2 ac3232
11 24 2 ac3232
12 24 2 ac3232
13 24 2 ac3232
14 24 2 ac3232
15 24 2 ac3232
1 25 2 ac3232
2 25 2 ac3232
3 25 2 ac3232
4 25 2 ac3232
5 25 2 ac3232
6 25 2 ac3232
7 25 2 ac3232
8 25 2 ac3232
9 25 2 ac3232
10 25 2 ac3232
11 25 2 ac3232
12 25 2 ac3232
13 25 2 ac3232
14 25 2 ac3232
15 25 2 ac3232
2 26 2 ac3232
3 26 2 ac3232
4 26 2 ac3232
5 26 2 ac3232
6 26 2 ac3232
7 26 2 ac3232
8 26 2 ac3232
9 26 2 ac3232
10 26 2 ac3232
11 26 2 ac3232
12 26 2 ac3232
13 26 2 ac3232
14 26 2 ac3232
15 26 2 ac3232
3 27 2 ac3232
4 27 2 ac3232
5 27 2 ac3232
6 27 2 ac3232
7 27 2 ac3232
8 27 2 ac3232
9 27 2 ac3232
10 27 2 ac3232
11 27 2 ac3232
12 27 2 ac3232
13 27 2 ac3232
14 27 2 ac3232
6 28 2 ac3232
7 28 2 ac3232
8 28 2 ac3232
9 28 2 ac3232
10 28 2 ac3232
11 28 2 ac3232
3 16 3 ac3232
4 16 3 ac3232
5 16 3 ac3232
6 16 3 ac3232
7 16 3 ac3232
8 16 3 ac3232
9 16 3 ac3232
10 16 3 ac3232
11 16 3 ac3232
12 16 3 ac3232
13 16 3 ac3232
14 16 3 ac3232
0 17 3 37946e
1 17 3 37946e
2 17 3 ac3232
3 17 3 ac3232
4 17 3 ac3232
5 17 3 ac3232
6 17 3 ac3232
7 17 3 ac3232
8 17 3 ac3232
9 17 3 ac3232
10 17 3 ac3232
11 17 3 ac3232
12 17 3 ac3232
13 17 3 ac3232
14 17 3 ac3232
15 17 3 ac3232
0 18 3 37946e
1 18 3 ac3232
2 18 3 ac3232
3 18 3 ac3232
4 18 3 ac3232
5 18 3 ac3232
6 18 3 ac3232
7 18 3 ac3232
8 18 3 ac3232
9 18 3 ac3232
10 18 3 ac3232
11 18 3 ac3232
12 18 3 ac3232
13 18 3 ac3232
14 18 3 ac3232
15 18 3 ac3232
1 19 3 ac3232
2 19 3 ac3232
3 19 3 ac3232
4 19 3 ac3232
5 19 3 ac3232
6 19 3 ac3232
7 19 3 ac3232
8 19 3 ac3232
9 19 3 ac3232
10 19 3 ac3232
11 19 3 ac3232
12 19 3 ac3232
13 19 3 ac3232
14 19 3 ac3232
15 19 3 ac3232
0 20 3 ac3232
1 20 3 ac3232
2 20 3 ac3232
3 20 3 ac3232
4 20 3 ac3232
5 20 3 ac3232
6 20 3 ac3232
7 20 3 ac3232
8 20 3 ac3232
9 20 3 ac3232
10 20 3 ac3232
11 20 3 ac3232
12 20 3 ac3232
13 20 3 ac3232
14 20 3 ac3232
15 20 3 ac3232
0 21 3 ac3232
1 21 3 ac3232
2 21 3 ac3232
3 21 3 ac3232
4 21 3 ac3232
5 21 3 ac3232
6 21 3 ac3232
7 21 3 ac3232
8 21 3 ac3232
9 21 3 ac3232
10 21 3 ac3232
11 21 3 ac3232
12 21 3 ac3232
13 21 3 ac3232
14 21 3 ac3232
15 21 3 ac3232
0 22 3 ac3232
1 22 3 ac3232
2 22 3 ac3232
3 22 3 ac3232
4 22 3 ac3232
5 22 3 ac3232
6 22 3 ac3232
7 22 3 ac3232
8 22 3 ac3232
9 22 3 ac3232
10 22 3 ac3232
11 22 3 ac3232
12 22 3 ac3232
13 22 3 ac3232
14 22 3 ac3232
15 22 3 ac3232
0 23 3 ac3232
1 23 3 ac3232
2 23 3 ac3232
3 23 3 ac3232
4 23 3 ac3232
5 23 3 ac3232
6 23 3 ac3232
7 23 3 ac3232
8 23 3 ac3232
9 23 3 ac3232
10 23 3 ac3232
11 23 3 ac3232
12 23 3 ac3232
13 23 3 ac3232
14 23 3 ac3232
15 23 3 ac3232
1 24 3 ac3232
2 24 3 ac3232
3 24 3 ac3232
4 24 3 ac3232
5 24 3 ac3232
6 24 3 ac3232
7 24 3 ac3232
8 24 3 ac3232
9 24 3 ac3232
10 24 3 ac3232
11 24 3 ac3232
12 24 3 ac3232
13 24 3 ac3232
14 24 3 ac3232
15 24 3 ac3232
1 25 3 ac3232
2 25 3 ac3232
3 25 3 ac3232
4 25 3 ac3232
5 25 3 ac3232
6 25 3 ac3232
7 25 3 ac3232
8 25 3 ac3232
9 25 3 ac3232
10 25 3 ac3232
11 25 3 ac3232
12 25 3 ac3232
13 25 3 ac3232
14 25 3 ac3232
15 25 3 ac3232
2 26 3 ac3232
3 26 3 ac3232
4 26 3 ac3232
5 26 3 ac3232
6 26 3 ac3232
7 26 3 ac3232
8 26 3 ac3232
9 26 3 ac3232
10 26 3 ac3232
11 26 3 ac3232
12 26 3 ac3232
13 26 3 ac3232
14 26 3 ac3232
15 26 3 ac3232
3 27 3 ac3232
4 27 3 ac3232
5 27 3 ac3232
6 27 3 ac3232
7 27 3 ac3232
8 27 3 ac3232
9 27 3 ac3232
10 27 3 ac3232
11 27 3 ac3232
12 27 3 ac3232
13 27 3 ac3232
14 27 3 ac3232
6 28 3 ac3232
7 28 3 ac3232
8 28 3 ac3232
9 28 3 ac3232
10 28 3 ac3232
11 28 3 ac3232
3 16 4 ac3232
4 16 4 ac3232
5 16 4 ac3232
6 16 4 ac3232
7 16 4 ac3232
8 16 4 ac3232
9 16 4 ac3232
10 16 4 ac3232
11 16 4 ac3232
12 16 4 ac3232
13 16 4 ac3232
14 16 4 ac3232
0 17 4 37946e
1 17 4 37946e
2 17 4 ac3232
3 17 4 ac3232
4 17 4 ac3232
5 17 4 ac3232
6 17 4 ac3232
7 17 4 ac3232
8 17 4 ac3232
9 17 4 ac3232
10 17 4 ac3232
11 17 4 ac3232
12 17 4 ac3232
13 17 4 ac3232
14 17 4 ac3232
15 17 4 ac3232
0 18 4 37946e
1 18 4 ac3232
2 18 4 ac3232
3 18 4 ac3232
4 18 4 ac3232
5 18 4 ac3232
6 18 4 ac3232
7 18 4 ac3232
8 18 4 ac3232
9 18 4 ac3232
10 18 4 ac3232
11 18 4 ac3232
12 18 4 ac3232
13 18 4 ac3232
14 18 4 ac3232
15 18 4 ac3232
1 19 4 ac3232
2 19 4 ac3232
3 19 4 ac3232
4 19 4 ac3232
5 19 4 ac3232
6 19 4 ac3232
7 19 4 ac3232
8 19 4 ac3232
9 19 4 ac3232
10 19 4 ac3232
11 19 4 ac3232
12 19 4 ac3232
13 19 4 ac3232
14 19 4 ac3232
15 19 4 ac3232
0 20 4 ac3232
1 20 4 ac3232
2 20 4 ac3232
3 20 4 ac3232
4 20 4 ac3232
5 20 4 ac3232
6 20 4 ac3232
7 20 4 ac3232
8 20 4 ac3232
9 20 4 ac3232
10 20 4 ac3232
11 20 4 ac3232
12 20 4 ac3232
13 20 4 ac3232
14 20 4 ac3232
15 20 4 ac3232
0 21 4 ac3232
1 21 4 ac3232
2 21 4 ac3232
3 21 4 ac3232
4 21 4 ac3232
5 21 4 ac3232
6 21 4 ac3232
7 21 4 ac3232
8 21 4 ac3232
9 21 4 ac3232
10 21 4 ac3232
11 21 4 ac3232
12 21 4 ac3232
13 21 4 ac3232
14 21 4 ac3232
15 21 4 ac3232
0 22 4 ac3232
1 22 4 ac3232
2 22 4 ac3232
3 22 4 ac3232
4 22 4 ac3232
5 22 4 ac3232
6 22 4 ac3232
7 22 4 ac3232
8 22 4 ac3232
9 22 4 ac3232
10 22 4 ac3232
11 22 4 ac3232
12 22 4 ac3232
13 22 4 ac3232
14 22 4 ac3232
15 22 4 ac3232
0 23 4 ac3232
1 23 4 ac3232
2 23 4 ac3232
3 23 4 ac3232
4 23 4 ac3232
5 23 4 ac3232
6 23 4 ac3232
7 23 4 ac3232
8 23 4 ac3232
9 23 4 ac3232
10 23 4 ac3232
11 23 4 ac3232
12 23 4 ac3232
13 23 4 ac3232
14 23 4 ac3232
15 23 4 ac3232
1 24 4 ac3232
2 24 4 ac3232
3 24 4 ac3232
4 24 4 ac3232
5 24 4 ac3232
6 24 4 ac3232
7 24 4 ac3232
8 24 4 ac3232
9 24 4 ac3232
10 24 4 ac3232
11 24 4 ac3232
12 24 4 ac3232
13 24 4 ac3232
14 24 4 ac3232
15 24 4 ac3232
1 25 4 ac3232
2 25 4 ac3232
3 25 4 ac3232
4 25 4 ac3232
5 25 4 ac3232
6 25 4 ac3232
7 25 4 ac3232
8 25 4 ac3232
9 25 4 ac3232
10 25 4 ac3232
11 25 4 ac3232
12 25 4 ac3232
13 25 4 ac3232
14 25 4 ac3232
15 25 4 ac3232
2 26 4 ac3232
3 26 4 ac3232
4 26 4 ac3232
5 26 4 ac3232
6 26 4 ac3232
7 26 4 ac3232
8 26 4 ac3232
9 26 4 ac3232
10 26 4 ac3232
11 26 4 ac3232
12 26 4 ac3232
13 26 4 ac3232
14 26 4 ac3232
15 26 4 ac3232
3 27 4 ac3232
4 27 4 ac3232
5 27 4 ac3232
6 27 4 ac3232
7 27 4 ac3232
8 27 4 ac3232
9 27 4 ac3232
10 27 4 ac3232
11 27 4 ac3232
12 27 4 ac3232
13 27 4 ac3232
14 27 4 ac3232
6 28 4 ac3232
7 28 4 ac3232
8 28 4 ac3232
9 28 4 ac3232
10 28 4 ac3232
11 28 4 ac3232
3 16 5 ac3232
4 16 5 ac3232
5 16 5 ac3232
6 16 5 ac3232
7 16 5 ac3232
8 16 5 ac3232
9 16 5 ac3232
10 16 5 ac3232
11 16 5 ac3232
12 16 5 ac3232
13 16 5 ac3232
14 16 5 ac3232
0 17 5 37946e
1 17 5 37946e
2 17 5 ac3232
3 17 5 ac3232
4 17 5 ac3232
5 17 5 ac3232
6 17 5 ac3232
7 17 5 ac3232
8 17 5 ac3232
9 17 5 ac3232
10 17 5 ac3232
11 17 5 ac3232
12 17 5 ac3232
13 17 5 ac3232
14 17 5 ac3232
15 17 5 ac3232
0 18 5 37946e
1 18 5 ac3232
2 18 5 ac3232
3 18 5 ac3232
4 18 5 ac3232
5 18 5 ac3232
6 18 5 ac3232
7 18 5 ac3232
8 18 5 ac3232
9 18 5 ac3232
10 18 5 ac3232
11 18 5 ac3232
12 18 5 ac3232
13 18 5 ac3232
14 18 5 ac3232
15 18 5 ac3232
1 19 5 ac3232
2 19 5 ac3232
3 19 5 ac3232
4 19 5 ac3232
5 19 5 ac3232
6 19 5 ac3232
7 19 5 ac3232
8 19 5 ac3232
9 19 5 ac3232
10 19 5 ac3232
11 19 5 ac3232
12 19 5 ac3232
13 19 5 ac3232
14 19 5 ac3232
15 19 5 ac3232
0 20 5 ac3232
1 20 5 ac3232
2 20 5 ac3232
3 20 5 ac3232
4 20 5 ac3232
5 20 5 ac3232
6 20 5 ac3232
7 20 5 ac3232
8 20 5 ac3232
9 20 5 ac3232
10 20 5 ac3232
11 20 5 ac3232
12 20 5 ac3232
13 20 5 ac3232
14 20 5 ac3232
15 20 5 ac3232
0 21 5 ac3232
1 21 5 ac3232
2 21 5 ac3232
3 21 5 ac3232
4 21 5 ac3232
5 21 5 ac3232
6 21 5 ac3232
7 21 5 ac3232
8 21 5 ac3232
9 21 5 ac3232
10 21 5 ac3232
11 21 5 ac3232
12 21 5 ac3232
13 21 5 ac3232
14 21 5 ac3232
15 21 5 ac3232
0 22 5 ac3232
1 22 5 ac3232
2 22 5 ac3232
3 22 5 ac3232
4 22 5 ac3232
5 22 5 ac3232
6 22 5 ac3232
7 22 5 ac3232
8 22 5 ac3232
9 22 5 ac3232
10 22 5 ac3232
11 22 5 ac3232
12 22 5 ac3232
13 22 5 ac3232
14 22 5 ac3232
15 22 5 ac3232
0 23 5 ac3232
1 23 5 ac3232
2 23 5 ac3232
3 23 5 ac3232
4 23 5 ac3232
5 23 5 ac3232
6 23 5 ac3232
7 23 5 ac3232
8 23 5 ac3232
9 23 5 ac3232
10 23 5 ac3232
11 23 5 ac3232
12 23 5 ac3232
13 23 5 ac3232
14 23 5 ac3232
15 23 5 ac3232
1 24 5 ac3232
2 24 5 ac3232
3 24 5 ac3232
4 24 5 ac3232
5 24 5 ac3232
6 24 5 ac3232
7 24 5 ac3232
8 24 5 ac3232
9 24 5 ac3232
10 24 5 ac3232
11 24 5 ac3232
12 24 5 ac3232
13 24 5 ac3232
14 24 5 ac3232
15 24 5 ac3232
1 25 5 ac3232
2 25 5 ac3232
3 25 5 ac3232
4 25 5 ac3232
5 25 5 ac3232
6 25 5 ac3232
7 25 5 ac3232
8 25 5 ac3232
9 25 5 ac3232
10 25 5 ac3232
11 25 5 ac3232
12 25 5 ac3232
13 25 5 ac3232
14 25 5 ac3232
15 25 5 ac3232
2 26 5 ac3232
3 26 5 ac3232
4 26 5 ac3232
5 26 5 ac3232
6 26 5 ac3232
7 26 5 ac3232
8 26 5 ac3232
9 26 5 ac3232
10 26 5 ac3232
11 26 5 ac3232
12 26 5 ac3232
13 26 5 ac3232
14 26 5 ac3232
15 26 5 ac3232
3 27 5 ac3232
4 27 5 ac3232
5 27 5 ac3232
6 27 5 ac3232
7 27 5 ac3232
8 27 5 ac3232
9 27 5 ac3232
10 27 5 ac3232
11 27 5 ac3232
12 27 5 ac3232
13 27 5 ac3232
14 27 5 ac3232
6 28 5 ac3232
7 28 5 ac3232
8 28 5 ac3232
9 28 5 ac3232
10 28 5 ac3232
11 28 5 ac3232
3 16 6 ac3232
4 16 6 ac3232
5 16 6 ac3232
6 16 6 ac3232
7 16 6 ac3232
8 16 6 ac3232
9 16 6 ac3232
10 16 6 ac3232
11 16 6 ac3232
12 16 6 ac3232
13 16 6 ac3232
14 16 6 ac3232
0 17 6 37946e
1 17 6 37946e
2 17 6 ac3232
3 17 6 ac3232
4 17 6 ac3232
5 17 6 ac3232
6 17 6 ac3232
7 17 6 ac3232
8 17 6 ac3232
9 17 6 ac3232
10 17 6 ac3232
11 17 6 ac3232
12 17 6 ac3232
13 17 6 ac3232
14 17 6 ac3232
15 17 6 ac3232
0 18 6 37946e
1 18 6 ac3232
2 18 6 ac3232
3 18 6 ac3232
4 18 6 ac3232
5 18 6 ac3232
6 18 6 ac3232
7 18 6 ac3232
8 18 6 ac3232
9 18 6 ac3232
10 18 6 ac3232
11 18 6 ac3232
12 18 6 ac3232
13 18 6 ac3232
14 18 6 ac3232
15 18 6 ac3232
1 19 6 ac3232
2 19 6 ac3232
3 19 6 ac3232
4 19 6 ac3232
5 19 6 ac3232
6 19 6 ac3232
7 19 6 ac3232
8 19 6 ac3232
9 19 6 ac3232
10 19 6 ac3232
11 19 6 ac3232
12 19 6 ac3232
13 19 6 ac3232
14 19 6 ac3232
15 19 6 ac3232
0 20 6 ac3232
1 20 6 ac3232
2 20 6 ac3232
3 20 6 ac3232
4 20 6 ac3232
5 20 6 ac3232
6 20 6 ac3232
7 20 6 ac3232
8 20 6 ac3232
9 20 6 ac3232
10 20 6 ac3232
11 20 6 ac3232
12 20 6 ac3232
13 20 6 ac3232
14 20 6 ac3232
15 20 6 ac3232
0 21 6 ac3232
1 21 6 ac3232
2 21 6 ac3232
3 21 6 ac3232
4 21 6 ac3232
5 21 6 ac3232
6 21 6 ac3232
7 21 6 ac3232
8 21 6 ac3232
9 21 6 ac3232
10 21 6 ac3232
11 21 6 ac3232
12 21 6 ac3232
13 21 6 ac3232
14 21 6 ac3232
15 21 6 ac3232
0 22 6 ac3232
1 22 6 ac3232
2 22 6 ac3232
3 22 6 ac3232
4 22 6 ac3232
5 22 6 ac3232
6 22 6 ac3232
7 22 6 ac3232
8 22 6 ac3232
9 22 6 ac3232
10 22 6 ac3232
11 22 6 ac3232
12 22 6 ac3232
13 22 6 ac3232
14 22 6 ac3232
15 22 6 ac3232
0 23 6 ac3232
1 23 6 ac3232
2 23 6 ac3232
3 23 6 ac3232
4 23 6 ac3232
5 23 6 ac3232
6 23 6 ac3232
7 23 6 ac3232
8 23 6 ac3232
9 23 6 ac3232
10 23 6 ac3232
11 23 6 ac3232
12 23 6 ac3232
13 23 6 ac3232
14 23 6 ac3232
15 23 6 ac3232
1 24 6 ac3232
2 24 6 ac3232
3 24 6 ac3232
4 24 6 ac3232
5 24 6 ac3232
6 24 6 ac3232
7 24 6 ac3232
8 24 6 ac3232
9 24 6 ac3232
10 24 6 ac3232
11 24 6 ac3232
12 24 6 ac3232
13 24 6 ac3232
14 24 6 ac3232
15 24 6 ac3232
1 25 6 ac3232
2 25 6 ac3232
3 25 6 ac3232
4 25 6 ac3232
5 25 6 ac3232
6 25 6 ac3232
7 25 6 ac3232
8 25 6 ac3232
9 25 6 ac3232
10 25 6 ac3232
11 25 6 ac3232
12 25 6 ac3232
13 25 6 ac3232
14 25 6 ac3232
15 25 6 ac3232
2 26 6 ac3232
3 26 6 ac3232
4 26 6 ac3232
5 26 6 ac3232
6 26 6 ac3232
7 26 6 ac3232
8 26 6 ac3232
9 26 6 ac3232
10 26 6 ac3232
11 26 6 ac3232
12 26 6 ac3232
13 26 6 ac3232
14 26 6 ac3232
15 26 6 ac3232
3 27 6 ac3232
4 27 6 ac3232
5 27 6 ac3232
6 27 6 ac3232
7 27 6 ac3232
8 27 6 ac3232
9 27 6 ac3232
10 27 6 ac3232
11 27 6 ac3232
12 27 6 ac3232
13 27 6 ac3232
14 27 6 ac3232
6 28 6 ac3232
7 28 6 ac3232
8 28 6 ac3232
9 28 6 ac3232
10 28 6 ac3232
11 28 6 ac3232
3 16 7 ac3232
4 16 7 ac3232
5 16 7 ac3232
6 16 7 ac3232
7 16 7 ac3232
8 16 7 ac3232
9 16 7 ac3232
10 16 7 ac3232
11 16 7 ac3232
12 16 7 ac3232
13 16 7 ac3232
14 16 7 ac3232
0 17 7 37946e
1 17 7 37946e
2 17 7 ac3232
3 17 7 ac3232
4 17 7 ac3232
5 17 7 ac3232
6 17 7 ac3232
7 17 7 ac3232
8 17 7 ac3232
9 17 7 ac3232
10 17 7 ac3232
11 17 7 ac3232
12 17 7 ac3232
13 17 7 ac3232
14 17 7 ac3232
15 17 7 ac3232
0 18 7 37946e
1 18 7 ac3232
2 18 7 ac3232
3 18 7 ac3232
4 18 7 ac3232
5 18 7 ac3232
6 18 7 ac3232
7 18 7 ac3232
8 18 7 ac3232
9 18 7 ac3232
10 18 7 ac3232
11 18 7 ac3232
12 18 7 ac3232
13 18 7 ac3232
14 18 7 ac3232
15 18 7 ac3232
1 19 7 ac3232
2 19 7 ac3232
3 19 7 ac3232
4 19 7 ac3232
5 19 7 ac3232
6 19 7 ac3232
7 19 7 ac3232
8 19 7 ac3232
9 19 7 ac3232
10 19 7 ac3232
11 19 7 ac3232
12 19 7 ac3232
13 19 7 ac3232
14 19 7 ac3232
15 19 7 ac3232
0 20 7 ac3232
1 20 7 ac3232
2 20 7 ac3232
3 20 7 ac3232
4 20 7 ac3232
5 20 7 ac3232
6 20 7 ac3232
7 20 7 ac3232
8 20 7 ac3232
9 20 7 ac3232
10 20 7 ac3232
11 20 7 ac3232
12 20 7 ac3232
13 20 7 ac3232
14 20 7 ac3232
15 20 7 ac3232
0 21 7 ac3232
1 21 7 ac3232
2 21 7 ac3232
3 21 7 ac3232
4 21 7 ac3232
5 21 7 ac3232
6 21 7 ac3232
7 21 7 ac3232
8 21 7 ac3232
9 21 7 ac3232
10 21 7 ac3232
11 21 7 ac3232
12 21 7 ac3232
13 21 7 ac3232
14 21 7 ac3232
15 21 7 ac3232
0 22 7 ac3232
1 22 7 ac3232
2 22 7 ac3232
3 22 7 ac3232
4 22 7 ac3232
5 22 7 ac3232
6 22 7 ac3232
7 22 7 ac3232
8 22 7 ac3232
9 22 7 ac3232
10 22 7 ac3232
11 22 7 ac3232
12 22 7 ac3232
13 22 7 ac3232
14 22 7 ac3232
15 22 7 ac3232
0 23 7 ac3232
1 23 7 ac3232
2 23 7 ac3232
3 23 7 ac3232
4 23 7 ac3232
5 23 7 ac3232
6 23 7 ac3232
7 23 7 ac3232
8 23 7 ac3232
9 23 7 ac3232
10 23 7 ac3232
11 23 7 ac3232
12 23 7 ac3232
13 23 7 ac3232
14 23 7 ac3232
15 23 7 ac3232
1 24 7 ac3232
2 24 7 ac3232
3 24 7 ac3232
4 24 7 ac3232
5 24 7 ac3232
6 24 7 ac3232
7 24 7 ac3232
8 24 7 ac3232
9 24 7 ac3232
10 24 7 ac3232
11 24 7 ac3232
12 24 7 ac3232
13 24 7 ac3232
14 24 7 ac3232
15 24 7 ac3232
1 25 7 ac3232
2 25 7 ac3232
3 25 7 ac3232
4 25 7 ac3232
5 25 7 ac3232
6 25 7 ac3232
7 25 7 ac3232
8 25 7 ac3232
9 25 7 ac3232
10 25 7 ac3232
11 25 7 ac3232
12 25 7 ac3232
13 25 7 ac3232
14 25 7 ac3232
15 25 7 ac3232
2 26 7 ac3232
3 26 7 ac3232
4 26 7 ac3232
5 26 7 ac3232
6 26 7 ac3232
7 26 7 ac3232
8 26 7 ac3232
9 26 7 ac3232
10 26 7 ac3232
11 26 7 ac3232
12 26 7 ac3232
13 26 7 ac3232
14 26 7 ac3232
15 26 7 ac3232
3 27 7 ac3232
4 27 7 ac3232
5 27 7 ac3232
6 27 7 ac3232
7 27 7 ac3232
8 27 7 ac3232
9 27 7 ac3232
10 27 7 ac3232
11 27 7 ac3232
12 27 7 ac3232
13 27 7 ac3232
14 27 7 ac3232
6 28 7 ac3232
7 28 7 ac3232
8 28 7 ac3232
9 28 7 ac3232
10 28 7 ac3232
11 28 7 ac3232
3 16 8 ac3232
4 16 8 ac3232
5 16 8 ac3232
6 16 8 ac3232
7 16 8 ac3232
8 16 8 ac3232
9 16 8 ac3232
10 16 8 ac3232
11 16 8 ac3232
12 16 8 ac3232
13 16 8 ac3232
14 16 8 ac3232
0 17 8 37946e
1 17 8 37946e
2 17 8 ac3232
3 17 8 ac3232
4 17 8 ac3232
5 17 8 ac3232
6 17 8 ac3232
7 17 8 ac3232
8 17 8 ac3232
9 17 8 ac3232
10 17 8 ac3232
11 17 8 ac3232
12 17 8 ac3232
13 17 8 ac3232
14 17 8 ac3232
15 17 8 ac3232
0 18 8 37946e
1 18 8 ac3232
2 18 8 ac3232
3 18 8 ac3232
4 18 8 ac3232
5 18 8 ac3232
6 18 8 ac3232
7 18 8 ac3232
8 18 8 ac3232
9 18 8 ac3232
10 18 8 ac3232
11 18 8 ac3232
12 18 8 ac3232
13 18 8 ac3232
14 18 8 ac3232
15 18 8 ac3232
1 19 8 ac3232
2 19 8 ac3232
3 19 8 ac3232
4 19 8 ac3232
5 19 8 ac3232
6 19 8 ac3232
7 19 8 ac3232
8 19 8 ac3232
9 19 8 ac3232
10 19 8 ac3232
11 19 8 ac3232
12 19 8 ac3232
13 19 8 ac3232
14 19 8 ac3232
15 19 8 ac3232
0 20 8 ac3232
1 20 8 ac3232
2 20 8 ac3232
3 20 8 ac3232
4 20 8 ac3232
5 20 8 ac3232
6 20 8 ac3232
7 20 8 ac3232
8 20 8 ac3232
9 20 8 ac3232
10 20 8 ac3232
11 20 8 ac3232
12 20 8 ac3232
13 20 8 ac3232
14 20 8 ac3232
15 20 8 ac3232
0 21 8 ac3232
1 21 8 ac3232
2 21 8 ac3232
3 21 8 ac3232
4 21 8 ac3232
5 21 8 ac3232
6 21 8 ac3232
7 21 8 ac3232
8 21 8 ac3232
9 21 8 ac3232
10 21 8 ac3232
11 21 8 ac3232
12 21 8 ac3232
13 21 8 ac3232
14 21 8 ac3232
15 21 8 ac3232
0 22 8 ac3232
1 22 8 ac3232
2 22 8 ac3232
3 22 8 ac3232
4 22 8 ac3232
5 22 8 ac3232
6 22 8 ac3232
7 22 8 ac3232
8 22 8 ac3232
9 22 8 ac3232
10 22 8 ac3232
11 22 8 ac3232
12 22 8 ac3232
13 22 8 ac3232
14 22 8 ac3232
15 22 8 ac3232
0 23 8 ac3232
1 23 8 ac3232
2 23 8 ac3232
3 23 8 ac3232
4 23 8 ac3232
5 23 8 ac3232
6 23 8 ac3232
7 23 8 ac3232
8 23 8 ac3232
9 23 8 ac3232
10 23 8 ac3232
11 23 8 ac3232
12 23 8 ac3232
13 23 8 ac3232
14 23 8 ac3232
15 23 8 ac3232
1 24 8 ac3232
2 24 8 ac3232
3 24 8 ac3232
4 24 8 ac3232
5 24 8 ac3232
6 24 8 ac3232
7 24 8 ac3232
8 24 8 ac3232
9 24 8 ac3232
10 24 8 ac3232
11 24 8 ac3232
12 24 8 ac3232
13 24 8 ac3232
14 24 8 ac3232
15 24 8 ac3232
1 25 8 ac3232
2 25 8 ac3232
3 25 8 ac3232
4 25 8 ac3232
5 25 8 ac3232
6 25 8 ac3232
7 25 8 ac3232
8 25 8 ac3232
9 25 8 ac3232
10 25 8 ac3232
11 25 8 ac3232
12 25 8 ac3232
13 25 8 ac3232
14 25 8 ac3232
15 25 8 ac3232
2 26 8 ac3232
3 26 8 ac3232
4 26 8 ac3232
5 26 8 ac3232
6 26 8 ac3232
7 26 8 ac3232
8 26 8 ac3232
9 26 8 ac3232
10 26 8 ac3232
11 26 8 ac3232
12 26 8 ac3232
13 26 8 ac3232
14 26 8 ac3232
15 26 8 ac3232
3 27 8 ac3232
4 27 8 ac3232
5 27 8 ac3232
6 27 8 ac3232
7 27 8 ac3232
8 27 8 ac3232
9 27 8 ac3232
10 27 8 ac3232
11 27 8 ac3232
12 27 8 ac3232
13 27 8 ac3232
14 27 8 ac3232
6 28 8 ac3232
7 28 8 ac3232
8 28 8 ac3232
9 28 8 ac3232
10 28 8 ac3232
11 28 8 ac3232
3 16 9 ac3232
4 16 9 ac3232
5 16 9 ac3232
6 16 9 ac3232
7 16 9 ac3232
8 16 9 ac3232
9 16 9 ac3232
10 16 9 ac3232
11 16 9 ac3232
12 16 9 ac3232
13 16 9 ac3232
14 16 9 ac3232
0 17 9 37946e
1 17 9 37946e
2 17 9 ac3232
3 17 9 ac3232
4 17 9 ac3232
5 17 9 ac3232
6 17 9 ac3232
7 17 9 ac3232
8 17 9 ac3232
9 17 9 ac3232
10 17 9 ac3232
11 17 9 ac3232
12 17 9 ac3232
13 17 9 ac3232
14 17 9 ac3232
15 17 9 ac3232
0 18 9 37946e
1 18 9 ac3232
2 18 9 ac3232
3 18 9 ac3232
4 18 9 ac3232
5 18 9 ac3232
6 18 9 ac3232
7 18 9 ac3232
8 18 9 ac3232
9 18 9 ac3232
10 18 9 ac3232
11 18 9 ac3232
12 18 9 ac3232
13 18 9 ac3232
14 18 9 ac3232
15 18 9 ac3232
1 19 9 ac3232
2 19 9 ac3232
3 19 9 ac3232
4 19 9 ac3232
5 19 9 ac3232
6 19 9 ac3232
7 19 9 ac3232
8 19 9 ac3232
9 19 9 ac3232
10 19 9 ac3232
11 19 9 ac3232
12 19 9 ac3232
13 19 9 ac3232
14 19 9 ac3232
15 19 9 ac3232
0 20 9 ac3232
1 20 9 ac3232
2 20 9 ac3232
3 20 9 ac3232
4 20 9 ac3232
5 20 9 ac3232
6 20 9 ac3232
7 20 9 ac3232
8 20 9 ac3232
9 20 9 ac3232
10 20 9 ac3232
11 20 9 ac3232
12 20 9 ac3232
13 20 9 ac3232
14 20 9 ac3232
15 20 9 ac3232
0 21 9 ac3232
1 21 9 ac3232
2 21 9 ac3232
3 21 9 ac3232
4 21 9 ac3232
5 21 9 ac3232
6 21 9 ac3232
7 21 9 ac3232
8 21 9 ac3232
9 21 9 ac3232
10 21 9 ac3232
11 21 9 ac3232
12 21 9 ac3232
13 21 9 ac3232
14 21 9 ac3232
15 21 9 ac3232
0 22 9 ac3232
1 22 9 ac3232
2 22 9 ac3232
3 22 9 ac3232
4 22 9 ac3232
5 22 9 ac3232
6 22 9 ac3232
7 22 9 ac3232
8 22 9 ac3232
9 22 9 ac3232
10 22 9 ac3232
11 22 9 ac3232
12 22 9 ac3232
13 22 9 ac3232
14 22 9 ac3232
15 22 9 ac3232
0 23 9 ac3232
1 23 9 ac3232
2 23 9 ac3232
3 23 9 ac3232
4 23 9 ac3232
5 23 9 ac3232
6 23 9 ac3232
7 23 9 ac3232
8 23 9 ac3232
9 23 9 ac3232
10 23 9 ac3232
11 23 9 ac3232
12 23 9 ac3232
13 23 9 ac3232
14 23 9 ac3232
15 23 9 ac3232
1 24 9 ac3232
2 24 9 ac3232
3 24 9 ac3232
4 24 9 ac3232
5 24 9 ac3232
6 24 9 ac3232
7 24 9 ac3232
8 24 9 ac3232
9 24 9 ac3232
10 24 9 ac3232
11 24 9 ac3232
12 24 9 ac3232
13 24 9 ac3232
14 24 9 ac3232
15 24 9 ac3232
1 25 9 ac3232
2 25 9 ac3232
3 25 9 ac3232
4 25 9 ac3232
5 25 9 ac3232
6 25 9 ac3232
7 25 9 ac3232
8 25 9 ac3232
9 25 9 ac3232
10 25 9 ac3232
11 25 9 ac3232
12 25 9 ac3232
13 25 9 ac3232
14 25 9 ac3232
15 25 9 ac3232
2 26 9 ac3232
3 26 9 ac3232
4 26 9 ac3232
5 26 9 ac3232
6 26 9 ac3232
7 26 9 ac3232
8 26 9 ac3232
9 26 9 ac3232
10 26 9 ac3232
11 26 9 ac3232
12 26 9 ac3232
13 26 9 ac3232
14 26 9 ac3232
15 26 9 ac3232
3 27 9 ac3232
4 27 9 ac3232
5 27 9 ac3232
6 27 9 ac3232
7 27 9 ac3232
8 27 9 ac3232
9 27 9 ac3232
10 27 9 ac3232
11 27 9 ac3232
12 27 9 ac3232
13 27 9 ac3232
14 27 9 ac3232
6 28 9 ac3232
7 28 9 ac3232
8 28 9 ac3232
9 28 9 ac3232
10 28 9 ac3232
11 28 9 ac3232
3 16 10 ac3232
4 16 10 ac3232
5 16 10 ac3232
6 16 10 ac3232
7 16 10 ac3232
8 16 10 ac3232
9 16 10 ac3232
10 16 10 ac3232
11 16 10 ac3232
12 16 10 ac3232
13 16 10 ac3232
14 16 10 ac3232
0 17 10 37946e
1 17 10 37946e
2 17 10 ac3232
3 17 10 ac3232
4 17 10 ac3232
5 17 10 ac3232
6 17 10 ac3232
7 17 10 ac3232
8 17 10 ac3232
9 17 10 ac3232
10 17 10 ac3232
11 17 10 ac3232
12 17 10 ac3232
13 17 10 ac3232
14 17 10 ac3232
15 17 10 ac3232
0 18 10 37946e
1 18 10 ac3232
2 18 10 ac3232
3 18 10 ac3232
4 18 10 ac3232
5 18 10 ac3232
6 18 10 ac3232
7 18 10 ac3232
8 18 10 ac3232
9 18 10 ac3232
10 18 10 ac3232
11 18 10 ac3232
12 18 10 ac3232
13 18 10 ac3232
14 18 10 ac3232
15 18 10 ac3232
1 19 10 ac3232
2 19 10 ac3232
3 19 10 ac3232
4 19 10 ac3232
5 19 10 ac3232
6 19 10 ac3232
7 19 10 ac3232
8 19 10 ac3232
9 19 10 ac3232
10 19 10 ac3232
11 19 10 ac3232
12 19 10 ac3232
13 19 10 ac3232
14 19 10 ac3232
15 19 10 ac3232
0 20 10 ac3232
1 20 10 ac3232
2 20 10 ac3232
3 20 10 ac3232
4 20 10 ac3232
5 20 10 ac3232
6 20 10 ac3232
7 20 10 ac3232
8 20 10 ac3232
9 20 10 ac3232
10 20 10 ac3232
11 20 10 ac3232
12 20 10 ac3232
13 20 10 ac3232
14 20 10 ac3232
15 20 10 ac3232
0 21 10 ac3232
1 21 10 ac3232
2 21 10 ac3232
3 21 10 ac3232
4 21 10 ac3232
5 21 10 ac3232
6 21 10 ac3232
7 21 10 ac3232
8 21 10 ac3232
9 21 10 ac3232
10 21 10 ac3232
11 21 10 ac3232
12 21 10 ac3232
13 21 10 ac3232
14 21 10 ac3232
15 21 10 ac3232
0 22 10 ac3232
1 22 10 ac3232
2 22 10 ac3232
3 22 10 ac3232
4 22 10 ac3232
5 22 10 ac3232
6 22 10 ac3232
7 22 10 ac3232
8 22 10 ac3232
9 22 10 ac3232
10 22 10 ac3232
11 22 10 ac3232
12 22 10 ac3232
13 22 10 ac3232
14 22 10 ac3232
15 22 10 ac3232
0 23 10 ac3232
1 23 10 ac3232
2 23 10 ac3232
3 23 10 ac3232
4 23 10 ac3232
5 23 10 ac3232
6 23 10 ac3232
7 23 10 ac3232
8 23 10 ac3232
9 23 10 ac3232
10 23 10 ac3232
11 23 10 ac3232
12 23 10 ac3232
13 23 10 ac3232
14 23 10 ac3232
15 23 10 ac3232
1 24 10 ac3232
2 24 10 ac3232
3 24 10 ac3232
4 24 10 ac3232
5 24 10 ac3232
6 24 10 ac3232
7 24 10 ac3232
8 24 10 ac3232
9 24 10 ac3232
10 24 10 ac3232
11 24 10 ac3232
12 24 10 ac3232
13 24 10 ac3232
14 24 10 ac3232
15 24 10 ac3232
1 25 10 ac3232
2 25 10 ac3232
3 25 10 ac3232
4 25 10 ac3232
5 25 10 ac3232
6 25 10 ac3232
7 25 10 ac3232
8 25 10 ac3232
9 25 10 ac3232
10 25 10 ac3232
11 25 10 ac3232
12 25 10 ac3232
13 25 10 ac3232
14 25 10 ac3232
15 25 10 ac3232
2 26 10 ac3232
3 26 10 ac3232
4 26 10 ac3232
5 26 10 ac3232
6 26 10 ac3232
7 26 10 ac3232
8 26 10 ac3232
9 26 10 ac3232
10 26 10 ac3232
11 26 10 ac3232
12 26 10 ac3232
13 26 10 ac3232
14 26 10 ac3232
15 26 10 ac3232
3 27 10 ac3232
4 27 10 ac3232
5 27 10 ac3232
6 27 10 ac3232
7 27 10 ac3232
8 27 10 ac3232
9 27 10 ac3232
10 27 10 ac3232
11 27 10 ac3232
12 27 10 ac3232
13 27 10 ac3232
14 27 10 ac3232
6 28 10 ac3232
7 28 10 ac3232
8 28 10 ac3232
9 28 10 ac3232
10 28 10 ac3232
11 28 10 ac3232
3 16 11 ac3232
4 16 11 ac3232
5 16 11 ac3232
6 16 11 ac3232
7 16 11 ac3232
8 16 11 ac3232
9 16 11 ac3232
10 16 11 ac3232
11 16 11 ac3232
12 16 11 ac3232
13 16 11 ac3232
14 16 11 ac3232
0 17 11 37946e
1 17 11 37946e
2 17 11 ac3232
3 17 11 ac3232
4 17 11 ac3232
5 17 11 ac3232
6 17 11 ac3232
7 17 11 ac3232
8 17 11 ac3232
9 17 11 ac3232
10 17 11 ac3232
11 17 11 ac3232
12 17 11 ac3232
13 17 11 ac3232
14 17 11 ac3232
15 17 11 ac3232
0 18 11 37946e
1 18 11 ac3232
2 18 11 ac3232
3 18 11 ac3232
4 18 11 ac3232
5 18 11 ac3232
6 18 11 ac3232
7 18 11 ac3232
8 18 11 ac3232
9 18 11 ac3232
10 18 11 ac3232
11 18 11 ac3232
12 18 11 ac3232
13 18 11 ac3232
14 18 11 ac3232
15 18 11 ac3232
1 19 11 ac3232
2 19 11 ac3232
3 19 11 ac3232
4 19 11 ac3232
5 19 11 ac3232
6 19 11 ac3232
7 19 11 ac3232
8 19 11 ac3232
9 19 11 ac3232
10 19 11 ac3232
11 19 11 ac3232
12 19 11 ac3232
13 19 11 ac3232
14 19 11 ac3232
15 19 11 ac3232
0 20 11 ac3232
1 20 11 ac3232
2 20 11 ac3232
3 20 11 ac3232
4 20 11 ac3232
5 20 11 ac3232
6 20 11 ac3232
7 20 11 ac3232
8 20 11 ac3232
9 20 11 ac3232
10 20 11 ac3232
11 20 11 ac3232
12 20 11 ac3232
13 20 11 ac3232
14 20 11 ac3232
15 20 11 ac3232
0 21 11 ac3232
1 21 11 ac3232
2 21 11 ac3232
3 21 11 ac3232
4 21 11 ac3232
5 21 11 ac3232
6 21 11 ac3232
7 21 11 ac3232
8 21 11 ac3232
9 21 11 ac3232
10 21 11 ac3232
11 21 11 ac3232
12 21 11 ac3232
13 21 11 ac3232
14 21 11 ac3232
15 21 11 ac3232
0 22 11 ac3232
1 22 11 ac3232
2 22 11 ac3232
3 22 11 ac3232
4 22 11 ac3232
5 22 11 ac3232
6 22 11 ac3232
7 22 11 ac3232
8 22 11 ac3232
9 22 11 ac3232
10 22 11 ac3232
11 22 11 ac3232
12 22 11 ac3232
13 22 11 ac3232
14 22 11 ac3232
15 22 11 ac3232
0 23 11 ac3232
1 23 11 ac3232
2 23 11 ac3232
3 23 11 ac3232
4 23 11 ac3232
5 23 11 ac3232
6 23 11 ac3232
7 23 11 ac3232
8 23 11 ac3232
9 23 11 ac3232
10 23 11 ac3232
11 23 11 ac3232
12 23 11 ac3232
13 23 11 ac3232
14 23 11 ac3232
15 23 11 ac3232
1 24 11 ac3232
2 24 11 ac3232
3 24 11 ac3232
4 24 11 ac3232
5 24 11 ac3232
6 24 11 ac3232
7 24 11 ac3232
8 24 11 ac3232
9 24 11 ac3232
10 24 11 ac3232
11 24 11 ac3232
12 24 11 ac3232
13 24 11 ac3232
14 24 11 ac3232
15 24 11 ac3232
1 25 11 ac3232
2 25 11 ac3232
3 25 11 ac3232
4 25 11 ac3232
5 25 11 ac3232
6 25 11 ac3232
7 25 11 ac3232
8 25 11 ac3232
9 25 11 ac3232
10 25 11 ac3232
11 25 11 ac3232
12 25 11 ac3232
13 25 11 ac3232
14 25 11 ac3232
15 25 11 ac3232
2 26 11 ac3232
3 26 11 ac3232
4 26 11 ac3232
5 26 11 ac3232
6 26 11 ac3232
7 26 11 ac3232
8 26 11 ac3232
9 26 11 ac3232
10 26 11 ac3232
11 26 11 ac3232
12 26 11 ac3232
13 26 11 ac3232
14 26 11 ac3232
15 26 11 ac3232
3 27 11 ac3232
4 27 11 ac3232
5 27 11 ac3232
6 27 11 ac3232
7 27 11 ac3232
8 27 11 ac3232
9 27 11 ac3232
10 27 11 ac3232
11 27 11 ac3232
12 27 11 ac3232
13 27 11 ac3232
14 27 11 ac3232
6 28 11 ac3232
7 28 11 ac3232
8 28 11 ac3232
9 28 11 ac3232
10 28 11 ac3232
11 28 11 ac3232
3 16 12 ac3232
4 16 12 ac3232
5 16 12 ac3232
6 16 12 ac3232
7 16 12 ac3232
8 16 12 ac3232
9 16 12 ac3232
10 16 12 ac3232
11 16 12 ac3232
12 16 12 ac3232
13 16 12 ac3232
14 16 12 ac3232
2 17 12 ac3232
3 17 12 ac3232
4 17 12 ac3232
5 17 12 ac3232
6 17 12 ac3232
7 17 12 ac3232
8 17 12 ac3232
9 17 12 ac3232
10 17 12 ac3232
11 17 12 ac3232
12 17 12 ac3232
13 17 12 ac3232
14 17 12 ac3232
15 17 12 ac3232
1 18 12 ac3232
2 18 12 ac3232
3 18 12 ac3232
4 18 12 ac3232
5 18 12 ac3232
6 18 12 ac3232
7 18 12 ac3232
8 18 12 ac3232
9 18 12 ac3232
10 18 12 ac3232
11 18 12 ac3232
12 18 12 ac3232
13 18 12 ac3232
14 18 12 ac3232
15 18 12 ac3232
1 19 12 ac3232
2 19 12 ac3232
3 19 12 ac3232
4 19 12 ac3232
5 19 12 ac3232
6 19 12 ac3232
7 19 12 ac3232
8 19 12 ac3232
9 19 12 ac3232
10 19 12 ac3232
11 19 12 ac3232
12 19 12 ac3232
13 19 12 ac3232
14 19 12 ac3232
15 19 12 ac3232
0 20 12 ac3232
1 20 12 ac3232
2 20 12 ac3232
3 20 12 ac3232
4 20 12 ac3232
5 20 12 ac3232
6 20 12 ac3232
7 20 12 ac3232
8 20 12 ac3232
9 20 12 ac3232
10 20 12 ac3232
11 20 12 ac3232
12 20 12 ac3232
13 20 12 ac3232
14 20 12 ac3232
15 20 12 ac3232
0 21 12 ac3232
1 21 12 ac3232
2 21 12 ac3232
3 21 12 ac3232
4 21 12 ac3232
5 21 12 ac3232
6 21 12 ac3232
7 21 12 ac3232
8 21 12 ac3232
9 21 12 ac3232
10 21 12 ac3232
11 21 12 ac3232
12 21 12 ac3232
13 21 12 ac3232
14 21 12 ac3232
15 21 12 ac3232
0 22 12 ac3232
1 22 12 ac3232
2 22 12 ac3232
3 22 12 ac3232
4 22 12 ac3232
5 22 12 ac3232
6 22 12 ac3232
7 22 12 ac3232
8 22 12 ac3232
9 22 12 ac3232
10 22 12 ac3232
11 22 12 ac3232
12 22 12 ac3232
13 22 12 ac3232
14 22 12 ac3232
15 22 12 ac3232
0 23 12 ac3232
1 23 12 ac3232
2 23 12 ac3232
3 23 12 ac3232
4 23 12 ac3232
5 23 12 ac3232
6 23 12 ac3232
7 23 12 ac3232
8 23 12 ac3232
9 23 12 ac3232
10 23 12 ac3232
11 23 12 ac3232
12 23 12 ac3232
13 23 12 ac3232
14 23 12 ac3232
15 23 12 ac3232
1 24 12 ac3232
2 24 12 ac3232
3 24 12 ac3232
4 24 12 ac3232
5 24 12 ac3232
6 24 12 ac3232
7 24 12 ac3232
8 24 12 ac3232
9 24 12 ac3232
10 24 12 ac3232
11 24 12 ac3232
12 24 12 ac3232
13 24 12 ac3232
14 24 12 ac3232
15 24 12 ac3232
1 25 12 ac3232
2 25 12 ac3232
3 25 12 ac3232
4 25 12 ac3232
5 25 12 ac3232
6 25 12 ac3232
7 25 12 ac3232
8 25 12 ac3232
9 25 12 ac3232
10 25 12 ac3232
11 25 12 ac3232
12 25 12 ac3232
13 25 12 ac3232
14 25 12 ac3232
15 25 12 ac3232
2 26 12 ac3232
3 26 12 ac3232
4 26 12 ac3232
5 26 12 ac3232
6 26 12 ac3232
7 26 12 ac3232
8 26 12 ac3232
9 26 12 ac3232
10 26 12 ac3232
11 26 12 ac3232
12 26 12 ac3232
13 26 12 ac3232
14 26 12 ac3232
15 26 12 ac3232
3 27 12 ac3232
4 27 12 ac3232
5 27 12 ac3232
6 27 12 ac3232
7 27 12 ac3232
8 27 12 ac3232
9 27 12 ac3232
10 27 12 ac3232
11 27 12 ac3232
12 27 12 ac3232
13 27 12 ac3232
14 27 12 ac3232
6 28 12 ac3232
7 28 12 ac3232
8 28 12 ac3232
9 28 12 ac3232
10 28 12 ac3232
11 28 12 ac3232
3 16 13 ac3232
4 16 13 ac3232
5 16 13 ac3232
6 16 13 ac3232
4 17 13 ac3232
5 17 13 ac3232
1 16 14 ac3232
2 16 14 ac3232
3 16 14 ac3232
4 16 14 ac3232
5 16 14 ac3232
6 16 14 ac3232
7 16 14 ac3232
8 16 14 ac3232
2 17 14 ac3232
3 17 14 ac3232
4 17 14 ac3232
5 17 14 ac3232
6 17 14 ac3232
7 17 14 ac3232
3 18 14 ac3232
4 18 14 ac3232
5 18 14 ac3232
6 18 14 ac3232
0 16 15 ac3232
1 16 15 ac3232
2 16 15 ac3232
3 16 15 ac3232
4 16 15 ac3232
5 16 15 ac3232
6 16 15 ac3232
7 16 15 ac3232
8 16 15 ac3232
9 16 15 ac3232
1 17 15 ac3232
2 17 15 ac3232
3 17 15 ac3232
4 17 15 ac3232
5 17 15 ac3232
6 17 15 ac3232
7 17 15 ac3232
8 17 15 ac3232
2 18 15 ac3232
3 18 15 ac3232
4 18 15 ac3232
5 18 15 ac3232
6 18 15 ac3232
7 18 15 ac3232
3 19 15 ac3232
4 19 15 ac3232
5 19 15 ac3232
6 19 15 ac3232
29 16 0 37946e
30 16 0 37946e
29 17 0 37946e
30 17 0 37946e
16 18 0 ac3232
30 18 0 37946e
16 19 0 ac3232
30 19 0 37946e
16 20 0 ac3232
17 20 0 ac3232
30 20 0 37946e
31 20 0 37946e
16 21 0 ac3232
17 21 0 ac3232
30 21 0 37946e
31 21 0 37946e
16 22 0 ac3232
17 22 0 ac3232
30 22 0 37946e
31 22 0 37946e
16 23 0 ac3232
17 23 0 ac3232
30 23 0 37946e
31 23 0 37946e
16 24 0 ac3232
30 24 0 37946e
31 24 0 37946e
16 25 0 ac3232
30 25 0 37946e
30 26 0 37946e
30 27 0 37946e
30 28 0 37946e
30 29 0 37946e
16 30 0 37946e
17 30 0 37946e
18 30 0 37946e
19 30 0 37946e
20 30 0 37946e
21 30 0 37946e
22 30 0 37946e
23 30 0 37946e
24 30 0 37946e
25 30 0 37946e
26 30 0 37946e
28 30 0 37946e
29 30 0 37946e
30 30 0 37946e
16 31 0 37946e
17 31 0 37946e
18 31 0 37946e
19 31 0 37946e
20 31 0 37946e
21 31 0 37946e
22 31 0 37946e
23 31 0 37946e
24 31 0 37946e
25 31 0 37946e
26 31 0 37946e
27 31 0 37946e
28 31 0 37946e
29 31 0 37946e
16 17 1 37946e
17 17 1 37946e
18 17 1 37946e
19 17 1 37946e
20 17 1 37946e
21 17 1 37946e
22 17 1 37946e
23 17 1 37946e
24 17 1 37946e
25 17 1 37946e
26 17 1 37946e
27 17 1 37946e
28 17 1 37946e
29 17 1 37946e
30 17 1 37946e
31 17 1 37946e
16 18 1 ac3232
17 18 1 37946e
18 18 1 37946e
19 18 1 37946e
20 18 1 37946e
21 18 1 37946e
22 18 1 37946e
23 18 1 37946e
24 18 1 37946e
25 18 1 37946e
26 18 1 37946e
27 18 1 37946e
28 18 1 37946e
29 18 1 37946e
30 18 1 37946e
31 18 1 37946e
16 19 1 ac3232
16 20 1 ac3232
17 20 1 ac3232
16 21 1 ac3232
17 21 1 ac3232
16 22 1 ac3232
17 22 1 ac3232
16 23 1 ac3232
17 23 1 ac3232
16 24 1 ac3232
16 25 1 ac3232
16 17 2 37946e
17 17 2 37946e
18 17 2 37946e
19 17 2 37946e
20 17 2 37946e
21 17 2 37946e
22 17 2 37946e
23 17 2 37946e
24 17 2 37946e
25 17 2 37946e
26 17 2 37946e
27 17 2 37946e
28 17 2 37946e
29 17 2 37946e
30 17 2 37946e
31 17 2 37946e
16 18 2 ac3232
17 18 2 37946e
18 18 2 37946e
19 18 2 37946e
20 18 2 37946e
21 18 2 37946e
22 18 2 37946e
23 18 2 37946e
24 18 2 37946e
25 18 2 37946e
26 18 2 37946e
27 18 2 37946e
28 18 2 37946e
29 18 2 37946e
30 18 2 37946e
31 18 2 37946e
16 19 2 ac3232
16 20 2 ac3232
17 20 2 ac3232
16 21 2 ac3232
17 21 2 ac3232
16 22 2 ac3232
17 22 2 ac3232
16 23 2 ac3232
17 23 2 ac3232
16 24 2 ac3232
16 25 2 ac3232
16 17 3 37946e
17 17 3 37946e
18 17 3 37946e
19 17 3 37946e
20 17 3 37946e
21 17 3 37946e
22 17 3 37946e
23 17 3 37946e
24 17 3 37946e
25 17 3 37946e
26 17 3 37946e
27 17 3 37946e
28 17 3 37946e
29 17 3 37946e
30 17 3 37946e
31 17 3 37946e
16 18 3 ac3232
17 18 3 37946e
18 18 3 37946e
19 18 3 37946e
20 18 3 37946e
21 18 3 37946e
22 18 3 37946e
23 18 3 37946e
24 18 3 37946e
25 18 3 37946e
26 18 3 37946e
27 18 3 37946e
28 18 3 37946e
29 18 3 37946e
30 18 3 37946e
31 18 3 37946e
16 19 3 ac3232
16 20 3 ac3232
17 20 3 ac3232
16 21 3 ac3232
17 21 3 ac3232
16 22 3 ac3232
17 22 3 ac3232
16 23 3 ac3232
17 23 3 ac3232
16 24 3 ac3232
16 25 3 ac3232
16 17 4 37946e
17 17 4 37946e
18 17 4 37946e
19 17 4 37946e
20 17 4 37946e
21 17 4 37946e
22 17 4 37946e
23 17 4 37946e
24 17 4 37946e
25 17 4 37946e
26 17 4 37946e
27 17 4 37946e
28 17 4 37946e
29 17 4 37946e
30 17 4 37946e
31 17 4 37946e
16 18 4 ac3232
17 18 4 37946e
18 18 4 37946e
19 18 4 37946e
20 18 4 37946e
21 18 4 37946e
22 18 4 37946e
23 18 4 37946e
24 18 4 37946e
25 18 4 37946e
26 18 4 37946e
27 18 4 37946e
28 18 4 37946e
29 18 4 37946e
30 18 4 37946e
31 18 4 37946e
16 19 4 ac3232
16 20 4 ac3232
17 20 4 ac3232
16 21 4 ac3232
17 21 4 ac3232
16 22 4 ac3232
17 22 4 ac3232
16 23 4 ac3232
17 23 4 ac3232
16 24 4 ac3232
16 25 4 ac3232
16 17 5 37946e
17 17 5 37946e
18 17 5 37946e
19 17 5 37946e
20 17 5 37946e
21 17 5 37946e
22 17 5 37946e
23 17 5 37946e
24 17 5 37946e
25 17 5 37946e
26 17 5 37946e
27 17 5 37946e
28 17 5 37946e
29 17 5 37946e
30 17 5 37946e
31 17 5 37946e
16 18 5 ac3232
17 18 5 37946e
18 18 5 37946e
19 18 5 37946e
20 18 5 37946e
21 18 5 37946e
22 18 5 37946e
23 18 5 37946e
24 18 5 37946e
25 18 5 37946e
26 18 5 37946e
27 18 5 37946e
28 18 5 37946e
29 18 5 37946e
30 18 5 37946e
31 18 5 37946e
16 19 5 ac3232
16 20 5 ac3232
17 20 5 ac3232
16 21 5 ac3232
17 21 5 ac3232
16 22 5 ac3232
17 22 5 ac3232
16 23 5 ac3232
17 23 5 ac3232
16 24 5 ac3232
16 25 5 ac3232
16 17 6 37946e
17 17 6 37946e
18 17 6 37946e
19 17 6 37946e
20 17 6 37946e
21 17 6 37946e
22 17 6 37946e
23 17 6 37946e
24 17 6 37946e
25 17 6 37946e
26 17 6 37946e
27 17 6 37946e
28 17 6 37946e
29 17 6 37946e
30 17 6 37946e
31 17 6 37946e
16 18 6 ac3232
17 18 6 37946e
18 18 6 37946e
19 18 6 37946e
20 18 6 37946e
21 18 6 37946e
22 18 6 37946e
23 18 6 37946e
24 18 6 37946e
25 18 6 37946e
26 18 6 37946e
27 18 6 37946e
28 18 6 37946e
29 18 6 37946e
30 18 6 37946e
31 18 6 37946e
16 19 6 ac3232
16 20 6 ac3232
17 20 6 ac3232
16 21 6 ac3232
17 21 6 ac3232
16 22 6 ac3232
17 22 6 ac3232
16 23 6 ac3232
17 23 6 ac3232
16 24 6 ac3232
16 25 6 ac3232
16 17 7 37946e
17 17 7 37946e
18 17 7 37946e
19 17 7 37946e
20 17 7 37946e
21 17 7 37946e
22 17 7 37946e
23 17 7 37946e
24 17 7 37946e
25 17 7 37946e
26 17 7 37946e
27 17 7 37946e
28 17 7 37946e
29 17 7 37946e
30 17 7 37946e
31 17 7 37946e
16 18 7 ac3232
17 18 7 37946e
18 18 7 37946e
19 18 7 37946e
20 18 7 37946e
21 18 7 37946e
22 18 7 37946e
23 18 7 37946e
24 18 7 37946e
25 18 7 37946e
26 18 7 37946e
27 18 7 37946e
28 18 7 37946e
29 18 7 37946e
30 18 7 37946e
31 18 7 37946e
16 19 7 ac3232
16 20 7 ac3232
17 20 7 ac3232
16 21 7 ac3232
17 21 7 ac3232
16 22 7 ac3232
17 22 7 ac3232
16 23 7 ac3232
17 23 7 ac3232
16 24 7 ac3232
16 25 7 ac3232
16 17 8 37946e
17 17 8 37946e
18 17 8 37946e
19 17 8 37946e
20 17 8 37946e
21 17 8 37946e
22 17 8 37946e
23 17 8 37946e
24 17 8 37946e
25 17 8 37946e
26 17 8 37946e
27 17 8 37946e
28 17 8 37946e
29 17 8 37946e
30 17 8 37946e
31 17 8 37946e
16 18 8 ac3232
17 18 8 37946e
18 18 8 37946e
19 18 8 37946e
20 18 8 37946e
21 18 8 37946e
22 18 8 37946e
23 18 8 37946e
24 18 8 37946e
25 18 8 37946e
26 18 8 37946e
27 18 8 37946e
28 18 8 37946e
29 18 8 37946e
30 18 8 37946e
31 18 8 37946e
16 19 8 ac3232
16 20 8 ac3232
17 20 8 ac3232
16 21 8 ac3232
17 21 8 ac3232
16 22 8 ac3232
17 22 8 ac3232
16 23 8 ac3232
17 23 8 ac3232
16 24 8 ac3232
16 25 8 ac3232
16 17 9 37946e
17 17 9 37946e
18 17 9 37946e
19 17 9 37946e
20 17 9 37946e
21 17 9 37946e
22 17 9 37946e
23 17 9 37946e
24 17 9 37946e
25 17 9 37946e
26 17 9 37946e
27 17 9 37946e
28 17 9 37946e
29 17 9 37946e
30 17 9 37946e
31 17 9 37946e
16 18 9 ac3232
17 18 9 37946e
18 18 9 37946e
19 18 9 37946e
20 18 9 37946e
21 18 9 37946e
22 18 9 37946e
23 18 9 37946e
24 18 9 37946e
25 18 9 37946e
26 18 9 37946e
27 18 9 37946e
28 18 9 37946e
29 18 9 37946e
30 18 9 37946e
31 18 9 37946e
16 19 9 ac3232
16 20 9 ac3232
17 20 9 ac3232
16 21 9 ac3232
17 21 9 ac3232
16 22 9 ac3232
17 22 9 ac3232
16 23 9 ac3232
17 23 9 ac3232
16 24 9 ac3232
16 25 9 ac3232
16 17 10 37946e
17 17 10 37946e
18 17 10 37946e
19 17 10 37946e
20 17 10 37946e
21 17 10 37946e
22 17 10 37946e
23 17 10 37946e
24 17 10 37946e
25 17 10 37946e
26 17 10 37946e
27 17 10 37946e
28 17 10 37946e
29 17 10 37946e
30 17 10 37946e
31 17 10 37946e
16 18 10 ac3232
17 18 10 37946e
18 18 10 37946e
19 18 10 37946e
20 18 10 37946e
21 18 10 37946e
22 18 10 37946e
23 18 10 37946e
24 18 10 37946e
25 18 10 37946e
26 18 10 37946e
27 18 10 37946e
28 18 10 37946e
29 18 10 37946e
30 18 10 37946e
31 18 10 37946e
16 19 10 ac3232
16 20 10 ac3232
17 20 10 ac3232
16 21 10 ac3232
17 21 10 ac3232
16 22 10 ac3232
17 22 10 ac3232
16 23 10 ac3232
17 23 10 ac3232
16 24 10 ac3232
16 25 10 ac3232
16 17 11 37946e
17 17 11 37946e
18 17 11 37946e
19 17 11 37946e
20 17 11 37946e
21 17 11 37946e
22 17 11 37946e
23 17 11 37946e
24 17 11 37946e
25 17 11 37946e
26 17 11 37946e
27 17 11 37946e
28 17 11 37946e
29 17 11 37946e
30 17 11 37946e
31 17 11 37946e
16 18 11 ac3232
17 18 11 37946e
18 18 11 37946e
19 18 11 37946e
20 18 11 37946e
21 18 11 37946e
22 18 11 37946e
23 18 11 37946e
24 18 11 37946e
25 18 11 37946e
26 18 11 37946e
27 18 11 37946e
28 18 11 37946e
29 18 11 37946e
30 18 11 37946e
31 18 11 37946e
16 19 11 ac3232
16 20 11 ac3232
17 20 11 ac3232
16 21 11 ac3232
17 21 11 ac3232
16 22 11 ac3232
17 22 11 ac3232
16 23 11 ac3232
17 23 11 ac3232
16 24 11 ac3232
16 25 11 ac3232
16 18 12 ac3232
16 19 12 ac3232
16 20 12 ac3232
17 20 12 ac3232
16 21 12 ac3232
17 21 12 ac3232
16 22 12 ac3232
17 22 12 ac3232
16 23 12 ac3232
17 23 12 ac3232
16 24 12 ac3232
16 25 12 ac3232
3 11 16 ac3232
4 11 16 ac3232
5 11 16 ac3232
6 11 16 ac3232
1 12 16 ac3232
2 12 16 ac3232
3 12 16 ac3232
4 12 16 ac3232
5 12 16 ac3232
6 12 16 ac3232
7 12 16 ac3232
8 12 16 ac3232
1 13 16 ac3232
2 13 16 ac3232
3 13 16 ac3232
4 13 16 ac3232
5 13 16 ac3232
6 13 16 ac3232
7 13 16 ac3232
8 13 16 ac3232
0 14 16 ac3232
1 14 16 ac3232
2 14 16 ac3232
3 14 16 ac3232
4 14 16 ac3232
5 14 16 ac3232
6 14 16 ac3232
7 14 16 ac3232
8 14 16 ac3232
9 14 16 ac3232
0 15 16 ac3232
1 15 16 ac3232
2 15 16 ac3232
3 15 16 ac3232
4 15 16 ac3232
5 15 16 ac3232
6 15 16 ac3232
7 15 16 ac3232
8 15 16 ac3232
9 15 16 ac3232
3 11 17 ac3232
4 11 17 ac3232
5 11 17 ac3232
6 11 17 ac3232
2 12 17 ac3232
3 12 17 ac3232
4 12 17 ac3232
5 12 17 ac3232
6 12 17 ac3232
7 12 17 ac3232
1 13 17 ac3232
2 13 17 ac3232
3 13 17 ac3232
4 13 17 ac3232
5 13 17 ac3232
6 13 17 ac3232
7 13 17 ac3232
8 13 17 ac3232
0 14 17 ac3232
1 14 17 ac3232
2 14 17 ac3232
3 14 17 ac3232
4 14 17 ac3232
5 14 17 ac3232
6 14 17 ac3232
7 14 17 ac3232
8 14 17 ac3232
9 14 17 ac3232
0 15 17 ac3232
1 15 17 ac3232
2 15 17 ac3232
3 15 17 ac3232
4 15 17 ac3232
5 15 17 ac3232
6 15 17 ac3232
7 15 17 ac3232
8 15 17 ac3232
9 15 17 ac3232
3 12 18 ac3232
4 12 18 ac3232
5 12 18 ac3232
6 12 18 ac3232
2 13 18 ac3232
3 13 18 ac3232
4 13 18 ac3232
5 13 18 ac3232
6 13 18 ac3232
7 13 18 ac3232
1 14 18 ac3232
2 14 18 ac3232
3 14 18 ac3232
4 14 18 ac3232
5 14 18 ac3232
6 14 18 ac3232
7 14 18 ac3232
8 14 18 ac3232
1 15 18 ac3232
2 15 18 ac3232
3 15 18 ac3232
4 15 18 ac3232
5 15 18 ac3232
6 15 18 ac3232
7 15 18 ac3232
8 15 18 ac3232
4 13 19 ac3232
5 13 19 ac3232
3 14 19 ac3232
4 14 19 ac3232
5 14 19 ac3232
6 14 19 ac3232
2 15 19 ac3232
3 15 19 ac3232
4 15 19 ac3232
5 15 19 ac3232
6 15 19 ac3232
7 15 19 ac3232
0 16 16 ac3232
1 16 16 ac3232
2 16 16 ac3232
3 16 16 ac3232
4 16 16 ac3232
5 16 16 ac3232
6 16 16 ac3232
7 16 16 ac3232
8 16 16 ac3232
9 16 16 ac3232
1 17 16 ac3232
2 17 16 ac3232
3 17 16 ac3232
4 17 16 ac3232
5 17 16 ac3232
6 17 16 ac3232
7 17 16 ac3232
8 17 16 ac3232
1 18 16 ac3232
2 18 16 ac3232
3 18 16 ac3232
4 18 16 ac3232
5 18 16 ac3232
6 18 16 ac3232
7 18 16 ac3232
8 18 16 ac3232
3 19 16 ac3232
4 19 16 ac3232
5 19 16 ac3232
6 19 16 ac3232
0 16 17 ac3232
1 16 17 ac3232
2 16 17 ac3232
3 16 17 ac3232
4 16 17 ac3232
5 16 17 ac3232
6 16 17 ac3232
7 16 17 ac3232
8 16 17 ac3232
9 16 17 ac3232
1 17 17 ac3232
2 17 17 ac3232
3 17 17 ac3232
4 17 17 ac3232
5 17 17 ac3232
6 17 17 ac3232
7 17 17 ac3232
8 17 17 ac3232
2 18 17 ac3232
3 18 17 ac3232
4 18 17 ac3232
5 18 17 ac3232
6 18 17 ac3232
7 18 17 ac3232
3 19 17 ac3232
4 19 17 ac3232
5 19 17 ac3232
6 19 17 ac3232
1 16 18 ac3232
2 16 18 ac3232
3 16 18 ac3232
4 16 18 ac3232
5 16 18 ac3232
6 16 18 ac3232
7 16 18 ac3232
8 16 18 ac3232
2 17 18 ac3232
3 17 18 ac3232
4 17 18 ac3232
5 17 18 ac3232
6 17 18 ac3232
7 17 18 ac3232
3 18 18 ac3232
4 18 18 ac3232
5 18 18 ac3232
6 18 18 ac3232
3 16 19 ac3232
4 16 19 ac3232
5 16 19 ac3232
6 16 19 ac3232
4 17 19 ac3232
5 17 19 ac3232
